Workbook

Sheet Cover
B2: Project Daylight - Clinuvel Pharmaceuticals (ASX: CUV / Nasdaq: CUVL)
B3: Private-equity take-private screening model | prepared 22-Sep-2026 from public information | A$ millions | FYE 30 June
B5: PROJECT | C5: Daylight
B6: Running case (MCASE) | C6: =MCASE -> 3
B7: Case label | C7: =MCASE!C8 -> Sponsor base | Base
B9: Key outputs - running case
B10: Offer price per share (A$) | C10: =LBO!D19 -> 10.75
B11: Premium to undisturbed (A$8.24) | C11: =LBO!D20 -> 0.30461165
B12: Equity purchase price (A$m) | C12: =LBO!D24 -> 544.81
B13: Implied TEV (A$m) | C13: =LBO!D29 -> 269.34096
B14: TEV / FY27E status-quo Adj. EBITDA | C14: =LBO!D33 -> 7.3798268
B15: TEV / FY28E post cost-out Adj. EBITDA | C15: =LBO!D35 -> 4.6841556
B16: Clinuvel cash applied (A$m) | C16: =LBO!D28 -> 235.46904
B17: New debt (A$m) | C17: =LBO!D74+LBO!D75 -> 75
B18: Equity invested (A$m) | C18: =LBO!D80 -> 251.39824
B19: 5-year MoIC | C19: =LBO!D255 -> 1.5929689
B20: 5-year IRR | C20: =LBO!D256 -> 0.10437355
B21: Max offer at 20% IRR (A$/sh) | C21: =ATP!C58 -> 9.2040734
B22: Model checks (0 = OK) | C22: =ROUND(ABS(LBO!D79)+SUMPRODUCT(ABS(LBO!G158:M158))+ABS(LBO!I105)+ABS(Contrib!C31)+ABS(ATP!C60),3) -> 0
B24: Tabs
B25: Hist | C25: Reported history FY20-FY26 and FY26A base-year inputs (reported vs estimated flagged)
B26: MCASE | C26: Master case driver - 23 cases (5 operating x 4 financing at the base offer + 3 variants)
B27: OPCASE | C27: Five operating cases: revenue by region, cost base, sponsor cost-out, capex, NWC
B28: FINCASE | C28: Four financing cases: base 2.0x private credit, high 3.0x + PIK, low 1.0x, no debt
B29: LBO | C29: Single-tab vertical model: S&U, PF BS, IS, BS, CF, debt, interest, credit, returns
B30: ATP | C30: Reverse LBO: max offer per share by exit multiple and hurdle IRR
B31: Contrib | C31: Value creation bridge (revenue, margin, multiple, cash generation, fees)
B32: Sensitivity | C32: Price x multiple grids; case capture table; op x fin matrices; probability-weighted view
B33: CVR | C33: Contingent value right design and valuation
B35: Colour code & mechanics
B36: Blue: hard-coded input
B37: Black: formula on same tab
B38: Green: link to another tab
B39: Iterative calculation must be ON (File > Options > Formulas; 1,000 iterations, 0.0000001). Average-balance interest (CIRC=1) and the Sensitivity capture cells are circular by design.
B40: To refresh the case tables: set MCASE to 1..23 in turn (or run model/run_cases.py), then back to the base case (3).
B42: Important
B43: Screening model built from public information only (company releases, press, third-party research summaries).
B44: Several inputs are analyst estimates, not disclosures: FY26 cost split by function, US/EU revenue split,
B45: working capital, dilutive securities, financing terms and all forward scenarios. They are flagged in the source notes.
B46: Not investment advice. Figures should be tied to the FY2026 annual report and 20-F before any use.

Sheet Hist
B2: Historical financials & FY26A base-year inputs
B3: A$m. Blue = reported or estimated input (see source column). Estimates flagged 'EST'/'ASSUMPTION'.
B5: Reported history (FY ending 30 June)
C6: FY20 | D6: FY21 | E6: FY22 | F6: FY23 | G6: FY24 | H6: FY25 | I6: FY26 | K6: Source / note
B7: Product revenue (SCENESSE) | C7: n.v. | D7: n.v. | E7: n.v. | F7: 77.9 | G7: 88 | H7: 95.018 | I7: 94.024 | K7: FY23 derived (FY24 +13% to A$88m, Morningstar); FY25 A$95.018m (Appendix 4E); FY26 A$94.024m
B8: Total revenues incl. interest & other income | C8: 32.565 | D8: 48.451 | E8: 66.987 | F8: 83 | G8: 95.31 | H8: 105.3 | I8: 101.153 | K8: As reported; FY20/FY21 'revenue' as reported (interest immaterial then)
B9: Total expenses | C9: n.v. | D9: n.v. | E9: n.v. | F9: n.v. | G9: 44.75 | H9: 53.7 | I9: 53.5 | K9: FY24 derived from FY25 +20%; FY25/FY26 as reported
B10: Profit before tax | C10: n.v. | D10: n.v. | E10: 34.321 | F10: n.v. | G10: 50.6 | H10: 51.6 | I10: 47.653 | K10: FY22 as reported (adj. PBT A$39.8m); FY24 derived (FY25 +2%); FY26 derived
B11: Net profit after tax | C11: 15.1 | D11: 24.728 | E11: 20.876 | F11: 30.605 | G11: 35.64 | H11: 36.2 | I11: 33.9 | K11: FY20 derived from FY21 +64%; FY22 as reported (non-cash items); others as reported
B12: Cash at year end | C12: n.v. | D12: n.v. | E12: 121.509 | F12: 157 | G12: 183.7 | H12: 224.1 | I12: 252.055 | K12: FY24 derived (FY25 +22%); others as reported
B13: Dividend per share (A$) | C13: n.v. | D13: n.v. | E13: 0.04 | F13: n.v. | G13: n.v. | H13: 0.05 | I13: 0.05 | K13: Fully franked where stated
B14: Product revenue growth | D14: =IFERROR(D7/C7-1,"") | E14: =IFERROR(E7/D7-1,"") | F14: =IFERROR(F7/E7-1,"") | G14: =IFERROR(G7/F7-1,"") -> 0.1296534 | H14: =IFERROR(H7/G7-1,"") -> 0.07975 | I14: =IFERROR(I7/H7-1,"") -> -0.010461176
B15: NPAT margin on total revenues | C15: =IFERROR(C11/C8,"") -> 0.46368801 | D15: =IFERROR(D11/D8,"") -> 0.5103713 | E15: =IFERROR(E11/E8,"") -> 0.31164256 | F15: =IFERROR(F11/F8,"") -> 0.36873494 | G15: =IFERROR(G11/G8,"") -> 0.37393768 | H15: =IFERROR(H11/H8,"") -> 0.34377968 | I15: =IFERROR(I11/I8,"") -> 0.33513588
B16: Half-year data: H1 FY26 sales A$36.93m (+4%), NPAT A$10.44m (-26%), cash A$233.0m; H1 interest A$5.26m (Appendix 4D, 26-Feb-2026). Implied H2 FY26 sales A$57.1m (c.-4% y/y).
B18: FY26A base-year inputs used by the LBO tab
B19: Item | C19: A$m | K19: Source / note
B20: Product revenue FY26A | C20: 94.024 | K20: Revenue from ordinary activities; FY26 results release, 27-Aug-2026 (GlobeNewswire/Nasdaq; 6-K)
B21: US share of product revenue | C21: 0.4 | K21: ASSUMPTION - US share of FY26 product revenue not in accessible disclosure; test 30-50%
B22: US SCENESSE revenue FY26A | C22: =C20*C21 -> 37.6096
B23: Europe & RoW SCENESSE revenue FY26A | C23: =C20-C22 -> 56.4144
B24: Total revenues incl. interest & other income | C24: 101.153 | K24: Total revenues incl. interest & other income; FY26 results release, 27-Aug-2026 (GlobeNewswire/Nasdaq; 6-K)
B25: Interest & other income (derived) | C25: =C24-C20 -> 7.129
B26: Total expenses (reported) | C26: 53.5 | K26: Total expenses; FY26 results release, 27-Aug-2026 (GlobeNewswire/Nasdaq; 6-K)
B27: Cost of goods / supply & distribution | C27: 7 | K27: EST: gross margin >90% (Kalkine, 2026)
B28: Core SCENESSE commercial, medical, PV & regulatory | C28: 11 | K28: EST: A$8-11m range (research stream)
B29: Corporate, listing & G&A | C29: 10.5 | K29: EST: A$8-11m range incl. ASX/SEC listing costs
B30: Communications, branding, marketing & consumer (CBM) | C30: 5 | K30: EST: CBM +100% in FY25; A$4-7m
B31: Vitiligo clinical program (CUV105/CUV107) | C31: 12 | K31: EST: A$10-15m; clinical dev. +215% in FY25
B32: Other R&D (Singapore, PRENUMBRA, NEURACTHEL, XP/VP) | C32: 6 | K32: EST: A$6-10m
B33: Depreciation & amortisation | C33: 2 | K33: EST
B34: Check: estimated split less reported expenses (should be 0) | C34: =SUM(C27:C33)-C26 -> 0
B35: Profit before tax (derived) | C35: =C24-C26 -> 47.653
B36: NPAT (reported) | C36: 33.9 | K36: NPAT (-6% y/y); FY26 results release, 27-Aug-2026 (GlobeNewswire/Nasdaq; 6-K)
B37: Income tax (derived) | C37: =C35-C36 -> 13.753
B38: Cash 30-Jun-2026 | C38: 252.055 | K38: Cash reserves (+12%); FY26 results release, 27-Aug-2026 (GlobeNewswire/Nasdaq; 6-K)
B39: Net assets 30-Jun-2026 | C39: 272.9 | K39: Net assets 30-Jun-2026; strategic reorganisation release 23-Jul-2026
B40: Net working capital & other operating items (est.) | C40: 15 | K40: ESTIMATE - net working capital & other net operating items (c.16% of sales)
B41: Operating cash flow FY26A (memo) | C41: 36.9 | K41: Operating cash inflow; FY26 results release, 27-Aug-2026 (GlobeNewswire/Nasdaq; 6-K)

Sheet MCASE
B2: Master case driver (MCASE)
B3: Change C5 to run any case. Every tab keys off the running row (row 8).
B5: MCASE | C5: 3
B7: Case # | C7: Case label | D7: Op case | E7: Fin case | F7: Offer price (A$/sh) | G7: Trans. exp. (% equity) | H7: Mgmt rollover (% equity) | I7: Exit multiple (x EBITDA) | J7: Min. cash (A$m) | K7: Comment
B8: =C5 -> 3 | C8: =OFFSET(C$9,$C$5-1,0,1,1) -> Sponsor base | Base | D8: =OFFSET(D$9,$C$5-1,0,1,1) -> 3 | E8: =OFFSET(E$9,$C$5-1,0,1,1) -> 1 | F8: =OFFSET(F$9,$C$5-1,0,1,1) -> 10.75 | G8: =OFFSET(G$9,$C$5-1,0,1,1) -> 0.0275 | H8: =OFFSET(H$9,$C$5-1,0,1,1) -> 0 | I8: =OFFSET(I$9,$C$5-1,0,1,1) -> 5.5 | J8: =OFFSET(J$9,$C$5-1,0,1,1) -> 40
B9: 1 | C9: Downside | Base | D9: 1 | E9: 1 | F9: 10.75 | G9: 0.0275 | H9: 0 | I9: 3.5 | J9: 40 | K9: Cases 1-20 = 5 operating x 4 financing cases at the base offer
B10: 2 | C10: Conservative | Base | D10: 2 | E10: 1 | F10: 10.75 | G10: 0.0275 | H10: 0 | I10: 4.5 | J10: 40
B11: 3 | C11: Sponsor base | Base | D11: 3 | E11: 1 | F11: 10.75 | G11: 0.0275 | H11: 0 | I11: 5.5 | J11: 40
B12: 4 | C12: Orals underwhelm | Base | D12: 4 | E12: 1 | F12: 10.75 | G12: 0.0275 | H12: 0 | I12: 7 | J12: 40
B13: 5 | C13: Upside (vitiligo) | Base | D13: 5 | E13: 1 | F13: 10.75 | G13: 0.0275 | H13: 0 | I13: 9 | J13: 40
B14: 6 | C14: Downside | High leverage | D14: 1 | E14: 2 | F14: 10.75 | G14: 0.0275 | H14: 0 | I14: 3.5 | J14: 40
B15: 7 | C15: Conservative | High leverage | D15: 2 | E15: 2 | F15: 10.75 | G15: 0.0275 | H15: 0 | I15: 4.5 | J15: 40
B16: 8 | C16: Sponsor base | High leverage | D16: 3 | E16: 2 | F16: 10.75 | G16: 0.0275 | H16: 0 | I16: 5.5 | J16: 40
B17: 9 | C17: Orals underwhelm | High leverage | D17: 4 | E17: 2 | F17: 10.75 | G17: 0.0275 | H17: 0 | I17: 7 | J17: 40
B18: 10 | C18: Upside (vitiligo) | High leverage | D18: 5 | E18: 2 | F18: 10.75 | G18: 0.0275 | H18: 0 | I18: 9 | J18: 40
B19: 11 | C19: Downside | Low leverage | D19: 1 | E19: 3 | F19: 10.75 | G19: 0.0275 | H19: 0 | I19: 3.5 | J19: 40
B20: 12 | C20: Conservative | Low leverage | D20: 2 | E20: 3 | F20: 10.75 | G20: 0.0275 | H20: 0 | I20: 4.5 | J20: 40
B21: 13 | C21: Sponsor base | Low leverage | D21: 3 | E21: 3 | F21: 10.75 | G21: 0.0275 | H21: 0 | I21: 5.5 | J21: 40
... B28: 20 | C28: Upside (vitiligo) | No acquisition debt | D28: 5 | E28: 4 | F28: 10.75 | G28: 0.0275 | H28: 0 | I28: 9 | J28: 40
B29: 21 | C29: Sponsor base | Base | CEO rolls 6.8% | D29: 3 | E29: 1 | F29: 10.75 | G29: 0.0275 | H29: 0.068 | I29: 5.5 | J29: 40 | K29: CEO rolls his c.6.8% stake (separate scheme class / GN19 protocol)
B30: 22 | C30: Sponsor base | Base | A$9.50 offer | D30: 3 | E30: 1 | F30: 9.5 | G30: 0.0275 | H30: 0 | I30: 5.5 | J30: 40 | K30: c.+15% premium to undisturbed
B31: 23 | C31: Sponsor base | Base | A$12.50 offer | D31: 3 | E31: 1 | F31: 12.5 | G31: 0.0275 | H31: 0 | I31: 5.5 | J31: 40 | K31: c.+52% premium; ~Mar-2026 trading levels
B32: 24 | C32: Base revenue, no cost-out | Base | D32: 6 | E32: 1 | F32: 10.75 | G32: 0.0275 | H32: 0 | I32: 5.5 | J32: 40 | K32: Tests how much of the thesis is cost-out: management plan, no savings
B35: Offer price context: undisturbed A$8.24 (1-Sep-2026); A$10.75 = c.+30% premium; cash per share at close c.A$5.4. Exit multiples scale with the durability of each operating case.

Sheet OPCASE
B2: Operating cases (OPCASE)
B3: Running block pulls the active case via OFFSET(case-1 cell, (OPCASE-1) x OpStep). FY27E = company status-quo plan (pre-close); FY28E-FY32E = sponsor plan.
B5: Running operating case (OPCASE) | C5: =MCASE!D8 -> 3
B6: OpStep (rows between case blocks) | C6: =ROW(B48)-ROW(B30) -> 18
B8: Running operating case (output - do not edit)
B9: Driver | C9: Unit | D9: Case description | H9: FY27E | I9: FY28E | J9: FY29E | K9: FY30E | L9: FY31E | M9: FY32E
B10: Case name / description | C10: =OFFSET(C$30,(OPCASE-1)*$C$6,0,1,1) -> Sponsor base | D10: =OFFSET(D$30,(OPCASE-1)*$C$6,0,1,1) -> Dersimelagon approved; APOLLO misses/delays bitopertin; SCENESSE keeps implant-preferring & severe patients
B11: US SCENESSE revenue growth | C11: % | H11: =OFFSET(H$31,(OPCASE-1)*$C$6,0,1,1) -> -0.05 | I11: =OFFSET(I$31,(OPCASE-1)*$C$6,0,1,1) -> -0.18 | J11: =OFFSET(J$31,(OPCASE-1)*$C$6,0,1,1) -> -0.15 | K11: =OFFSET(K$31,(OPCASE-1)*$C$6,0,1,1) -> -0.08 | L11: =OFFSET(L$31,(OPCASE-1)*$C$6,0,1,1) -> -0.05 | M11: =OFFSET(M$31,(OPCASE-1)*$C$6,0,1,1) -> -0.03
B12: Europe & RoW SCENESSE revenue growth | C12: % | H12: =OFFSET(H$32,(OPCASE-1)*$C$6,0,1,1) -> 0.05 | I12: =OFFSET(I$32,(OPCASE-1)*$C$6,0,1,1) -> 0.04 | J12: =OFFSET(J$32,(OPCASE-1)*$C$6,0,1,1) -> 0.02 | K12: =OFFSET(K$32,(OPCASE-1)*$C$6,0,1,1) -> -0.03 | L12: =OFFSET(L$32,(OPCASE-1)*$C$6,0,1,1) -> -0.05 | M12: =OFFSET(M$32,(OPCASE-1)*$C$6,0,1,1) -> -0.03
B13: Vitiligo revenue | C13: A$m | H13: =OFFSET(H$33,(OPCASE-1)*$C$6,0,1,1) -> 0 | I13: =OFFSET(I$33,(OPCASE-1)*$C$6,0,1,1) -> 0 | J13: =OFFSET(J$33,(OPCASE-1)*$C$6,0,1,1) -> 0 | K13: =OFFSET(K$33,(OPCASE-1)*$C$6,0,1,1) -> 0 | L13: =OFFSET(L$33,(OPCASE-1)*$C$6,0,1,1) -> 0 | M13: =OFFSET(M$33,(OPCASE-1)*$C$6,0,1,1) -> 0
B14: Other new product revenue | C14: A$m | H14: =OFFSET(H$34,(OPCASE-1)*$C$6,0,1,1) -> 0 | I14: =OFFSET(I$34,(OPCASE-1)*$C$6,0,1,1) -> 0 | J14: =OFFSET(J$34,(OPCASE-1)*$C$6,0,1,1) -> 0 | K14: =OFFSET(K$34,(OPCASE-1)*$C$6,0,1,1) -> 0 | L14: =OFFSET(L$34,(OPCASE-1)*$C$6,0,1,1) -> 0 | M14: =OFFSET(M$34,(OPCASE-1)*$C$6,0,1,1) -> 0
B15: COGS % of revenue | C15: % | H15: =OFFSET(H$35,(OPCASE-1)*$C$6,0,1,1) -> 0.075 | I15: =OFFSET(I$35,(OPCASE-1)*$C$6,0,1,1) -> 0.075 | J15: =OFFSET(J$35,(OPCASE-1)*$C$6,0,1,1) -> 0.075 | K15: =OFFSET(K$35,(OPCASE-1)*$C$6,0,1,1) -> 0.075 | L15: =OFFSET(L$35,(OPCASE-1)*$C$6,0,1,1) -> 0.075 | M15: =OFFSET(M$35,(OPCASE-1)*$C$6,0,1,1) -> 0.075
B16: Core & corporate cost inflation | C16: % | H16: =OFFSET(H$36,(OPCASE-1)*$C$6,0,1,1) -> 0.03 | I16: =OFFSET(I$36,(OPCASE-1)*$C$6,0,1,1) -> 0.03 | J16: =OFFSET(J$36,(OPCASE-1)*$C$6,0,1,1) -> 0.03 | K16: =OFFSET(K$36,(OPCASE-1)*$C$6,0,1,1) -> 0.03 | L16: =OFFSET(L$36,(OPCASE-1)*$C$6,0,1,1) -> 0.03 | M16: =OFFSET(M$36,(OPCASE-1)*$C$6,0,1,1) -> 0.03
B17: Competitive-defence spend (patient services, access) | C17: A$m | H17: =OFFSET(H$37,(OPCASE-1)*$C$6,0,1,1) -> 0 | I17: =OFFSET(I$37,(OPCASE-1)*$C$6,0,1,1) -> -1.5 | J17: =OFFSET(J$37,(OPCASE-1)*$C$6,0,1,1) -> -1.5 | K17: =OFFSET(K$37,(OPCASE-1)*$C$6,0,1,1) -> -1 | L17: =OFFSET(L$37,(OPCASE-1)*$C$6,0,1,1) -> -1 | M17: =OFFSET(M$37,(OPCASE-1)*$C$6,0,1,1) -> -1
B18: Sponsor corporate cost savings (% of status quo) | C18: % | H18: =OFFSET(H$38,(OPCASE-1)*$C$6,0,1,1) -> 0 | I18: =OFFSET(I$38,(OPCASE-1)*$C$6,0,1,1) -> 0.35 | J18: =OFFSET(J$38,(OPCASE-1)*$C$6,0,1,1) -> 0.45 | K18: =OFFSET(K$38,(OPCASE-1)*$C$6,0,1,1) -> 0.45 | L18: =OFFSET(L$38,(OPCASE-1)*$C$6,0,1,1) -> 0.45 | M18: =OFFSET(M$38,(OPCASE-1)*$C$6,0,1,1) -> 0.45
B19: CBM & consumer spend | C19: A$m | H19: =OFFSET(H$39,(OPCASE-1)*$C$6,0,1,1) -> -5.2 | I19: =OFFSET(I$39,(OPCASE-1)*$C$6,0,1,1) -> -1 | J19: =OFFSET(J$39,(OPCASE-1)*$C$6,0,1,1) -> -1 | K19: =OFFSET(K$39,(OPCASE-1)*$C$6,0,1,1) -> -1 | L19: =OFFSET(L$39,(OPCASE-1)*$C$6,0,1,1) -> -1 | M19: =OFFSET(M$39,(OPCASE-1)*$C$6,0,1,1) -> -1
B20: Vitiligo clinical spend | C20: A$m | H20: =OFFSET(H$40,(OPCASE-1)*$C$6,0,1,1) -> -15 | I20: =OFFSET(I$40,(OPCASE-1)*$C$6,0,1,1) -> -2 | J20: =OFFSET(J$40,(OPCASE-1)*$C$6,0,1,1) -> 0 | K20: =OFFSET(K$40,(OPCASE-1)*$C$6,0,1,1) -> 0 | L20: =OFFSET(L$40,(OPCASE-1)*$C$6,0,1,1) -> 0 | M20: =OFFSET(M$40,(OPCASE-1)*$C$6,0,1,1) -> 0
B21: Other R&D spend | C21: A$m | H21: =OFFSET(H$41,(OPCASE-1)*$C$6,0,1,1) -> -6.5 | I21: =OFFSET(I$41,(OPCASE-1)*$C$6,0,1,1) -> -1.5 | J21: =OFFSET(J$41,(OPCASE-1)*$C$6,0,1,1) -> -1.5 | K21: =OFFSET(K$41,(OPCASE-1)*$C$6,0,1,1) -> -1.5 | L21: =OFFSET(L$41,(OPCASE-1)*$C$6,0,1,1) -> -1.5 | M21: =OFFSET(M$41,(OPCASE-1)*$C$6,0,1,1) -> -1.5
B22: Vitiligo launch & commercial costs | C22: A$m | H22: =OFFSET(H$42,(OPCASE-1)*$C$6,0,1,1) -> 0 | I22: =OFFSET(I$42,(OPCASE-1)*$C$6,0,1,1) -> 0 | J22: =OFFSET(J$42,(OPCASE-1)*$C$6,0,1,1) -> 0 | K22: =OFFSET(K$42,(OPCASE-1)*$C$6,0,1,1) -> 0 | L22: =OFFSET(L$42,(OPCASE-1)*$C$6,0,1,1) -> 0 | M22: =OFFSET(M$42,(OPCASE-1)*$C$6,0,1,1) -> 0
B23: Non-recurring items (relocation, restructuring) | C23: A$m | H23: =OFFSET(H$43,(OPCASE-1)*$C$6,0,1,1) -> -4 | I23: =OFFSET(I$43,(OPCASE-1)*$C$6,0,1,1) -> -4 | J23: =OFFSET(J$43,(OPCASE-1)*$C$6,0,1,1) -> 0 | K23: =OFFSET(K$43,(OPCASE-1)*$C$6,0,1,1) -> 0 | L23: =OFFSET(L$43,(OPCASE-1)*$C$6,0,1,1) -> 0 | M23: =OFFSET(M$43,(OPCASE-1)*$C$6,0,1,1) -> 0
B24: Capex | C24: A$m | H24: =OFFSET(H$44,(OPCASE-1)*$C$6,0,1,1) -> -4 | I24: =OFFSET(I$44,(OPCASE-1)*$C$6,0,1,1) -> -1.5 | J24: =OFFSET(J$44,(OPCASE-1)*$C$6,0,1,1) -> -1.5 | K24: =OFFSET(K$44,(OPCASE-1)*$C$6,0,1,1) -> -1.5 | L24: =OFFSET(L$44,(OPCASE-1)*$C$6,0,1,1) -> -1.5 | M24: =OFFSET(M$44,(OPCASE-1)*$C$6,0,1,1) -> -1.5
B25: Net working capital % of revenue | C25: % | H25: =OFFSET(H$45,(OPCASE-1)*$C$6,0,1,1) -> 0.16 | I25: =OFFSET(I$45,(OPCASE-1)*$C$6,0,1,1) -> 0.16 | J25: =OFFSET(J$45,(OPCASE-1)*$C$6,0,1,1) -> 0.16 | K25: =OFFSET(K$45,(OPCASE-1)*$C$6,0,1,1) -> 0.16 | L25: =OFFSET(L$45,(OPCASE-1)*$C$6,0,1,1) -> 0.16 | M25: =OFFSET(M$45,(OPCASE-1)*$C$6,0,1,1) -> 0.16
B29: Operating case 1: Downside
B30: Case 1 | C30: Downside | D30: Both orals approved (dersimelagon ~Feb-27, bitopertin ~mid-27) and adopted fast; EU oral from FY29; price pressure
B31: US SCENESSE revenue growth | C31: % | H31: -0.08 | I31: -0.35 | J31: -0.35 | K31: -0.25 | L31: -0.2 | M31: -0.15
B32: Europe & RoW SCENESSE revenue growth | C32: % | H32: 0.04 | I32: 0.02 | J32: -0.05 | K32: -0.15 | L32: -0.2 | M32: -0.15
B33: Vitiligo revenue | C33: A$m | H33: 0 | I33: 0 | J33: 0 | K33: 0 | L33: 0 | M33: 0
B34: Other new product revenue | C34: A$m | H34: 0 | I34: 0 | J34: 0 | K34: 0 | L34: 0 | M34: 0
B35: COGS % of revenue | C35: % | H35: 0.075 | I35: 0.08 | J35: 0.085 | K35: 0.09 | L35: 0.095 | M35: 0.1
B36: Core & corporate cost inflation | C36: % | H36: 0.03 | I36: 0.03 | J36: 0.03 | K36: 0.03 | L36: 0.03 | M36: 0.03
B37: Competitive-defence spend (patient services, access) | C37: A$m | H37: 0 | I37: -2 | J37: -2 | K37: -1.5 | L37: -1 | M37: -1
B38: Sponsor corporate cost savings (% of status quo) | C38: % | H38: 0 | I38: 0.35 | J38: 0.45 | K38: 0.45 | L38: 0.45 | M38: 0.45
B39: CBM & consumer spend | C39: A$m | H39: -5.2 | I39: -1 | J39: -1 | K39: -1 | L39: -1 | M39: -1
B40: Vitiligo clinical spend | C40: A$m | H40: -15 | I40: -2 | J40: 0 | K40: 0 | L40: 0 | M40: 0
B41: Other R&D spend | C41: A$m | H41: -6.5 | I41: -1.5 | J41: -1.5 | K41: -1.5 | L41: -1.5 | M41: -1.5
B42: Vitiligo launch & commercial costs | C42: A$m | H42: 0 | I42: 0 | J42: 0 | K42: 0 | L42: 0 | M42: 0
... B45: Net working capital % of revenue | C45: % | H45: 0.16 | I45: 0.16 | J45: 0.16 | K45: 0.16 | L45: 0.16 | M45: 0.16
B47: Operating case 2: Conservative
B48: Case 2 | C48: Conservative | D48: Dersimelagon approved Feb-27 with solid uptake; bitopertin also approved; EU competition from FY30
B49: US SCENESSE revenue growth | C49: % | H49: -0.06 | I49: -0.25 | J49: -0.25 | K49: -0.15 | L49: -0.1 | M49: -0.08
...

Sheet FINCASE
B2: Financing cases (FINCASE)
B3: Running output = OFFSET(case-1 cell, (FINCASE-1) x FinStep). Terms are indicative specialist private-credit terms for a single-product orphan asset (no term sheet).
B5: Running financing case (FINCASE) | E5: =MCASE!E8 -> 1
B6: FinStep (rows between case blocks) | E6: =ROW(B54)-ROW(B34) -> 20
B8: Running financing assumptions (output - do not edit)
B9: Case name | E9: =OFFSET(E$34,(FINCASE-1)*$E$6,0,1,1) -> Base (specialist private credit)
B10: Unitranche term loan (x FY27E Adj. EBITDA) | E10: =OFFSET(E$35,(FINCASE-1)*$E$6,0,1,1) -> 2 | G10: Leverage sized on FY27E (status-quo) Adj. EBITDA, i.e. before sponsor cost-out; 5% amortisation reflects lender caution on a single product facing new entrants.
B11: Term loan margin over base rate | E11: =OFFSET(E$36,(FINCASE-1)*$E$6,0,1,1) -> 0.06
B12: Term loan base-rate floor | E12: =OFFSET(E$37,(FINCASE-1)*$E$6,0,1,1) -> 0
B13: Term loan upfront fee / OID | E13: =OFFSET(E$38,(FINCASE-1)*$E$6,0,1,1) -> 0.025
B14: Term loan mandatory amortisation (% p.a.) | E14: =OFFSET(E$39,(FINCASE-1)*$E$6,0,1,1) -> 0.05
B15: Term loan tenor (years) | E15: =OFFSET(E$40,(FINCASE-1)*$E$6,0,1,1) -> 5
B16: HoldCo PIK notes (x FY27E Adj. EBITDA) | E16: =OFFSET(E$41,(FINCASE-1)*$E$6,0,1,1) -> 0
B17: PIK coupon | E17: =OFFSET(E$42,(FINCASE-1)*$E$6,0,1,1) -> 0.12
B18: PIK upfront fee | E18: =OFFSET(E$43,(FINCASE-1)*$E$6,0,1,1) -> 0.02
B19: PIK tenor (years) | E19: =OFFSET(E$44,(FINCASE-1)*$E$6,0,1,1) -> 6
B20: Revolver commitment (A$m) | E20: =OFFSET(E$45,(FINCASE-1)*$E$6,0,1,1) -> 20
B21: Revolver margin | E21: =OFFSET(E$46,(FINCASE-1)*$E$6,0,1,1) -> 0.04
B22: Revolver commitment fee (on undrawn) | E22: =OFFSET(E$47,(FINCASE-1)*$E$6,0,1,1) -> 0.014
B23: Revolver upfront fee | E23: =OFFSET(E$48,(FINCASE-1)*$E$6,0,1,1) -> 0.01
B24: Revolver tenor (years) | E24: =OFFSET(E$49,(FINCASE-1)*$E$6,0,1,1) -> 5
B25: Covenant: max net debt / EBITDA | E25: =OFFSET(E$50,(FINCASE-1)*$E$6,0,1,1) -> 3
B26: Covenant: min EBITDA / cash interest | E26: =OFFSET(E$51,(FINCASE-1)*$E$6,0,1,1) -> 3
B33: Financing case 1: Base (specialist private credit)
B34: Case 1 | E34: Base (specialist private credit)
B35: Unitranche term loan (x FY27E Adj. EBITDA) | E35: 2
B36: Term loan margin over base rate | E36: 0.06
B37: Term loan base-rate floor | E37: 0
B38: Term loan upfront fee / OID | E38: 0.025
B39: Term loan mandatory amortisation (% p.a.) | E39: 0.05
B40: Term loan tenor (years) | E40: 5
B41: HoldCo PIK notes (x FY27E Adj. EBITDA) | E41: 0
B42: PIK coupon | E42: 0.12
B43: PIK upfront fee | E43: 0.02
B44: PIK tenor (years) | E44: 6
B45: Revolver commitment (A$m) | E45: 20
B46: Revolver margin | E46: 0.04
... B51: Covenant: min EBITDA / cash interest | E51: 3
B53: Financing case 2: High leverage (+ HoldCo PIK)
B54: Case 2 | E54: High leverage (+ HoldCo PIK)
...

Sheet LBO
B2: Project Daylight - Clinuvel Pharmaceuticals take-private: screening LBO
B3: A$ millions unless stated | FYE 30 June | Close assumed 30-Jun-2027 (end FY27E) | 5-year hold to FY32E | blue = input, black = formula, green = link
B5: CIRC switch (1 = average-balance interest; iterative calc on) | D5: 1
B6: Running master case (MCASE) | D6: =MCASE -> 3
B7: Case label | D7: =MCASE!C8 -> Sponsor base | Base
B8: Operating case / financing case | D8: =MCASE!D8 -> 3 | E8: =MCASE!E8 -> 1
B9: Operating case description | D9: =OPCASE!D10 -> Dersimelagon approved; APOLLO misses/delays bitopertin; SCENESSE keeps implant-preferring & severe patients
B11: Timeline
B12: Fiscal year | G12: FY26A | H12: FY27E | I12: FY28E | J12: FY29E | K12: FY30E | L12: FY31E | M12: FY32E
B13: Period end | G13: =DATE(2026,6,30) -> 46203 | H13: =DATE(YEAR(G13)+1,6,30) -> 46568 | I13: =DATE(YEAR(H13)+1,6,30) -> 46934 | J13: =DATE(YEAR(I13)+1,6,30) -> 47299 | K13: =DATE(YEAR(J13)+1,6,30) -> 47664 | L13: =DATE(YEAR(K13)+1,6,30) -> 48029 | M13: =DATE(YEAR(L13)+1,6,30) -> 48395
B14: Period | G14: Actual | H14: Status quo | I14: Sponsor | J14: Sponsor | K14: Sponsor | L14: Sponsor | M14: Sponsor
B15: Years since close | I15: =YEAR(I13)-YEAR($H$13) -> 1 | J15: =YEAR(J13)-YEAR($H$13) -> 2 | K15: =YEAR(K13)-YEAR($H$13) -> 3 | L15: =YEAR(L13)-YEAR($H$13) -> 4 | M15: =YEAR(M13)-YEAR($H$13) -> 5
B17: Transaction assumptions
B18: Undisturbed share price (A$) | C18: ASX close 1-Sep-2026 (A$9.18 on 27-Aug results day, -12.7%); CUVL US$5.85 on 16-Sep | D18: 8.24
B19: Offer price per share (A$) | C19: MCASE running row | D19: =MCASE!F8 -> 10.75
B20: Premium to undisturbed | D20: =D19/D18-1 -> 0.30461165
B21: Basic shares outstanding (m) | C21: Derived: Vanguard 2,523,018 sh = 5.003% (Form 603, 14-Aug-2026) | D21: 50.43
B22: Dilutive securities (m) | C22: EST: performance rights; CEO holds no LTI (Jul-2026 terms) | D22: 0.25
B23: Fully diluted shares (m) | D23: =D21+D22 -> 50.68
B24: Equity purchase price | D24: =D19*D23 -> 544.81
B25: Clinuvel cash at close (pre-deal, FY27E) | C25: Status-quo FY27E closing cash (cash flow section) | D25: =H175 -> 275.46904
B26: Existing debt refinanced | C26: No borrowings (leases ignored) | D26: 0
B27: Minimum operating cash retained | C27: Named MIN_CASH | D27: =MCASE!J8 -> 40
B28: Clinuvel cash applied to the transaction | D28: =MAX(0,D25-D27) -> 235.46904
B29: Implied transaction enterprise value (TEV) | D29: =D24+D26-D25 -> 269.34096
B30: LTM Adj. EBITDA at close (FY27E, status quo) | D30: =H129 -> 36.496922
B31: FY26A Adj. EBITDA | D31: =G129 -> 42.524
B32: FY28E Adj. EBITDA (first sponsor year) | D32: =I129 -> 57.50043
B33: TEV / LTM (FY27E) Adj. EBITDA | D33: =D29/D30 -> 7.3798268
B34: TEV / FY26A Adj. EBITDA | D34: =D29/D31 -> 6.3338577
B35: TEV / FY28E Adj. EBITDA (post cost-out) | D35: =D29/D32 -> 4.6841556
B36: TEV / FY27E revenue | D36: =D29/H113 -> 2.8362357
B37: Equity purchase price / FY26A NPAT | D37: =D24/G141 -> 16.071091
B38: Cash per fully diluted share at close (A$) | D38: =D25/D23 -> 5.4354585
B39: Transaction expenses (% of equity purchase price) | D39: =MCASE!G8 -> 0.0275
B40: Transaction expenses | C40: Advisers, legal, IER, scheme, FIRB/ACCC, US counsel | D40: =D39*D24 -> 14.982275
B41: Management rollover (% of equity purchase price) | D41: =MCASE!H8 -> 0
B42: Management rollover | D42: =D41*D24 -> 0
B43: Exit multiple (x LTM Adj. EBITDA) | D43: =MCASE!I8 -> 5.5
B44: Exit costs (% of TEV) | C44: Sell-side fees at exit, % of TEV | D44: 0.015
...

Sheet ATP
B2: Ability to pay (reverse LBO) - running case
B3: Max offer per share that still earns the hurdle IRR, given the running operating/financing case (Y5 exit). Cash flows include interim distributions.
B5: FY32E LTM Adj. EBITDA | C5: =LBO!M129 -> 46.359082 | K5: Max equity = NPV at the hurdle of distributions (Y1-Y4) plus Y5 distribution and exit equity. Max price = (max equity + cash applied + new debt - financing fees) / (1 + fee%) / FD shares. Debt and cash applied do not depend on price.
B6: FY32E debt | C6: =LBO!M155 -> 0
B7: FY32E cash | C7: =LBO!M146 -> 40
B8: Exit costs (% TEV) | C8: =LBO!D44 -> 0.015
B9: Interim distributions Y1-Y5 are discounted at each hurdle
B10: Clinuvel cash applied at close | C10: =LBO!D28 -> 235.46904
B11: New debt raised at close | C11: =LBO!D73+LBO!D74+LBO!D75 -> 75
B12: Financing fees | C12: =LBO!D69 -> 2.075
B13: Transaction expenses (% of equity price) | C13: =LBO!D39 -> 0.0275
B14: Fully diluted shares (m) | C14: =LBO!D23 -> 50.68
B15: Undisturbed price (A$) | C15: =LBO!D18 -> 8.24
B16: Pre-deal cash at close | C16: =LBO!D25 -> 275.46904
B17: LTM (FY27E) Adj. EBITDA | C17: =LBO!D30 -> 36.496922
B19: Max equity invested (A$m) | C19: 0.15 | D19: 0.2 | E19: 0.25
B20: Exit at 3.0x LTM EBITDA | C20: =(NPV(C$19,LBO!I245:L245)+(LBO!M245+($G20*$C$5*(1-$C$8)-$C$6+$C$7))/(1+C$19)^5) -> 151.43307 | D20: =(NPV(D$19,LBO!I245:L245)+(LBO!M245+($G20*$C$5*(1-$C$8)-$C$6+$C$7))/(1+D$19)^5) -> 125.01808 | E20: =(NPV(E$19,LBO!I245:L245)+(LBO!M245+($G20*$C$5*(1-$C$8)-$C$6+$C$7))/(1+E$19)^5) -> 104.13281 | G20: 3
B21: Exit at 4.0x LTM EBITDA | C21: =(NPV(C$19,LBO!I245:L245)+(LBO!M245+($G21*$C$5*(1-$C$8)-$C$6+$C$7))/(1+C$19)^5) -> 174.136 | D21: =(NPV(D$19,LBO!I245:L245)+(LBO!M245+($G21*$C$5*(1-$C$8)-$C$6+$C$7))/(1+D$19)^5) -> 143.3693 | E21: =(NPV(E$19,LBO!I245:L245)+(LBO!M245+($G21*$C$5*(1-$C$8)-$C$6+$C$7))/(1+E$19)^5) -> 119.09589 | G21: 4
B22: Exit at 5.0x LTM EBITDA | C22: =(NPV(C$19,LBO!I245:L245)+(LBO!M245+($G22*$C$5*(1-$C$8)-$C$6+$C$7))/(1+C$19)^5) -> 196.83893 | D22: =(NPV(D$19,LBO!I245:L245)+(LBO!M245+($G22*$C$5*(1-$C$8)-$C$6+$C$7))/(1+D$19)^5) -> 161.72051 | E22: =(NPV(E$19,LBO!I245:L245)+(LBO!M245+($G22*$C$5*(1-$C$8)-$C$6+$C$7))/(1+E$19)^5) -> 134.05897 | G22: 5
B23: Exit at 6.0x LTM EBITDA | C23: =(NPV(C$19,LBO!I245:L245)+(LBO!M245+($G23*$C$5*(1-$C$8)-$C$6+$C$7))/(1+C$19)^5) -> 219.54185 | D23: =(NPV(D$19,LBO!I245:L245)+(LBO!M245+($G23*$C$5*(1-$C$8)-$C$6+$C$7))/(1+D$19)^5) -> 180.07173 | E23: =(NPV(E$19,LBO!I245:L245)+(LBO!M245+($G23*$C$5*(1-$C$8)-$C$6+$C$7))/(1+E$19)^5) -> 149.02205 | G23: 6
B24: Exit at 7.0x LTM EBITDA | C24: =(NPV(C$19,LBO!I245:L245)+(LBO!M245+($G24*$C$5*(1-$C$8)-$C$6+$C$7))/(1+C$19)^5) -> 242.24478 | D24: =(NPV(D$19,LBO!I245:L245)+(LBO!M245+($G24*$C$5*(1-$C$8)-$C$6+$C$7))/(1+D$19)^5) -> 198.42294 | E24: =(NPV(E$19,LBO!I245:L245)+(LBO!M245+($G24*$C$5*(1-$C$8)-$C$6+$C$7))/(1+E$19)^5) -> 163.98513 | G24: 7
B25: Exit at 8.0x LTM EBITDA | C25: =(NPV(C$19,LBO!I245:L245)+(LBO!M245+($G25*$C$5*(1-$C$8)-$C$6+$C$7))/(1+C$19)^5) -> 264.94771 | D25: =(NPV(D$19,LBO!I245:L245)+(LBO!M245+($G25*$C$5*(1-$C$8)-$C$6+$C$7))/(1+D$19)^5) -> 216.77416 | E25: =(NPV(E$19,LBO!I245:L245)+(LBO!M245+($G25*$C$5*(1-$C$8)-$C$6+$C$7))/(1+E$19)^5) -> 178.94821 | G25: 8
B26: Exit at 9.0x LTM EBITDA | C26: =(NPV(C$19,LBO!I245:L245)+(LBO!M245+($G26*$C$5*(1-$C$8)-$C$6+$C$7))/(1+C$19)^5) -> 287.65063 | D26: =(NPV(D$19,LBO!I245:L245)+(LBO!M245+($G26*$C$5*(1-$C$8)-$C$6+$C$7))/(1+D$19)^5) -> 235.12537 | E26: =(NPV(E$19,LBO!I245:L245)+(LBO!M245+($G26*$C$5*(1-$C$8)-$C$6+$C$7))/(1+E$19)^5) -> 193.91129 | G26: 9
B28: Max offer price per share (A$) | C28: 0.15 | D28: 0.2 | E28: 0.25
B29: Exit at 3.0x LTM EBITDA | C29: =(C20+$C$10+$C$11-$C$12)/(1+$C$13)/$C$14 -> 8.8303137 | D29: =(D20+$C$10+$C$11-$C$12)/(1+$C$13)/$C$14 -> 8.3230521 | E29: =(E20+$C$10+$C$11-$C$12)/(1+$C$13)/$C$14 -> 7.9219807 | G29: 3
B30: Exit at 4.0x LTM EBITDA | C30: =(C21+$C$10+$C$11-$C$12)/(1+$C$13)/$C$14 -> 9.2662906 | D30: =(D21+$C$10+$C$11-$C$12)/(1+$C$13)/$C$14 -> 8.6754606 | E30: =(E21+$C$10+$C$11-$C$12)/(1+$C$13)/$C$14 -> 8.209325 | G30: 4
B31: Exit at 5.0x LTM EBITDA | C31: =(C22+$C$10+$C$11-$C$12)/(1+$C$13)/$C$14 -> 9.7022674 | D31: =(D22+$C$10+$C$11-$C$12)/(1+$C$13)/$C$14 -> 9.0278691 | E31: =(E22+$C$10+$C$11-$C$12)/(1+$C$13)/$C$14 -> 8.4966693 | G31: 5
B32: Exit at 6.0x LTM EBITDA | C32: =(C23+$C$10+$C$11-$C$12)/(1+$C$13)/$C$14 -> 10.138244 | D32: =(D23+$C$10+$C$11-$C$12)/(1+$C$13)/$C$14 -> 9.3802776 | E32: =(E23+$C$10+$C$11-$C$12)/(1+$C$13)/$C$14 -> 8.7840135 | G32: 6
B33: Exit at 7.0x LTM EBITDA | C33: =(C24+$C$10+$C$11-$C$12)/(1+$C$13)/$C$14 -> 10.574221 | D33: =(D24+$C$10+$C$11-$C$12)/(1+$C$13)/$C$14 -> 9.7326862 | E33: =(E24+$C$10+$C$11-$C$12)/(1+$C$13)/$C$14 -> 9.0713578 | G33: 7
B34: Exit at 8.0x LTM EBITDA | C34: =(C25+$C$10+$C$11-$C$12)/(1+$C$13)/$C$14 -> 11.010198 | D34: =(D25+$C$10+$C$11-$C$12)/(1+$C$13)/$C$14 -> 10.085095 | E34: =(E25+$C$10+$C$11-$C$12)/(1+$C$13)/$C$14 -> 9.3587021 | G34: 8
B35: Exit at 9.0x LTM EBITDA | C35: =(C26+$C$10+$C$11-$C$12)/(1+$C$13)/$C$14 -> 11.446175 | D35: =(D26+$C$10+$C$11-$C$12)/(1+$C$13)/$C$14 -> 10.437503 | E35: =(E26+$C$10+$C$11-$C$12)/(1+$C$13)/$C$14 -> 9.6460464 | G35: 9
B37: Implied premium to undisturbed | C37: 0.15 | D37: 0.2 | E37: 0.25
B38: Exit at 3.0x LTM EBITDA | C38: =C29/$C$15-1 -> 0.071640016 | D38: =D29/$C$15-1 -> 0.01007914 | E38: =E29/$C$15-1 -> -0.038594575 | G38: 3
B39: Exit at 4.0x LTM EBITDA | C39: =C30/$C$15-1 -> 0.12454983 | D39: =D30/$C$15-1 -> 0.052847163 | E39: =E30/$C$15-1 -> -0.0037226966 | G39: 4
B40: Exit at 5.0x LTM EBITDA | C40: =C31/$C$15-1 -> 0.17745964 | D40: =D31/$C$15-1 -> 0.095615187 | E40: =E31/$C$15-1 -> 0.031149182 | G40: 5
B41: Exit at 6.0x LTM EBITDA | C41: =C32/$C$15-1 -> 0.23036945 | D41: =D32/$C$15-1 -> 0.13838321 | E41: =E32/$C$15-1 -> 0.06602106 | G41: 6
B42: Exit at 7.0x LTM EBITDA | C42: =C33/$C$15-1 -> 0.28327926 | D42: =D33/$C$15-1 -> 0.18115123 | E42: =E33/$C$15-1 -> 0.10089294 | G42: 7
B43: Exit at 8.0x LTM EBITDA | C43: =C34/$C$15-1 -> 0.33618907 | D43: =D34/$C$15-1 -> 0.22391926 | E43: =E34/$C$15-1 -> 0.13576482 | G43: 8
B44: Exit at 9.0x LTM EBITDA | C44: =C35/$C$15-1 -> 0.38909888 | D44: =D35/$C$15-1 -> 0.26668728 | E44: =E35/$C$15-1 -> 0.17063669 | G44: 9
B46: Implied TEV / LTM Adj. EBITDA | C46: 0.15 | D46: 0.2 | E46: 0.25
...

Sheet Contrib
B2: Value creation bridge - running case (entry at close to Y5 exit)
B3: Decomposes (exit equity + distributions - equity invested). Entry multiple is on status-quo FY27E EBITDA, so the EBITDA bucket includes the sponsor cost-out.
B5: Entry TEV (implied by offer) | C5: =LBO!D29 -> 269.34096 | F5: Reading the bridge: a declining single-product asset should show negative revenue effect and multiple contraction, offset by cost-out (margin effect) and cash generation. If most value comes from cash generation, the deal is a 'cash-box' harvest rather than an operational growth story.
B6: Entry LTM Adj. EBITDA (FY27E) | C6: =LBO!H129 -> 36.496922
B7: Entry multiple | C7: =C5/C6 -> 7.3798268
B8: Entry revenue (FY27E) | C8: =LBO!H113 -> 94.96424
B9: Entry Adj. EBITDA margin | C9: =C6/C8 -> 0.38432279
B10: Exit LTM Adj. EBITDA (FY32E) | C10: =LBO!M129 -> 46.359082
B11: Exit multiple | C11: =LBO!D43 -> 5.5
B12: Exit TEV | C12: =LBO!M240 -> 254.97495
B13: Exit revenue (FY32E) | C13: =LBO!M113 -> 77.279255
B14: Exit Adj. EBITDA margin | C14: =C10/C13 -> 0.59989038
B15: PF net debt at close | C15: =LBO!I102-LBO!I93 -> 35
B16: Net debt at exit | C16: =LBO!M155-LBO!M146 -> -40
B17: Cumulative distributions | C17: =LBO!M246 -> 109.31924
B18: Entry fees (transaction + financing) | C18: =-(LBO!D68+LBO!D69) -> -17.057275
B19: Exit costs | C19: =LBO!M243 -> -3.8246242
B20: Equity invested | C20: =LBO!D80 -> 251.39824
B21: Exit equity value | C21: =LBO!M244 -> 291.15032
B23: Bridge | C23: A$m | D23: % of total
B24: EBITDA growth: revenue effect [(Rev1-Rev0) x margin0 x m0] | C24: =(C13-C8)*C9*C7 -> -50.158786 | D24: =C24/$C$30 -> -0.33647507
B25: EBITDA growth: margin effect [(mgn1-mgn0) x Rev1 x m0] | C25: =(C14-C9)*C13*C7 -> 122.93982 | D25: =C25/$C$30 -> 0.82470462
B26: Multiple expansion / (contraction) [(m1-m0) x EBITDA1] | C26: =(C11-C7)*C10 -> -87.147044 | D26: =C26/$C$30 -> -0.58459963
B27: Deleveraging & cash generation [ND0 - ND1 + distributions] | C27: =C15-C16+C17 -> 184.31924 | D27: =C27/$C$30 -> 1.23645
B28: Entry fees | C28: =C18 -> -17.057275 | D28: =C28/$C$30 -> -0.11442358
B29: Exit costs | C29: =C19 -> -3.8246242 | D29: =C29/$C$30 -> -0.025656337
B30: Total value created | C30: =SUM(C24:C29) -> 149.07133 | D30: =C30/$C$30 -> 1
B31: Check: exit equity + distributions - invested - bridge (should be 0) | C31: =C21+C17-C20-C30 -> 0

Sheet Sensitivity
B2: Sensitivity & case outputs
B3: Block A-B: live formulas (running case; helper cash flows in columns AL-AQ). Block C: self-referencing capture cells - run every MCASE (model/run_cases.py or cycle MCASE in Excel with iteration on). Blocks D-F read the captured values.
AL4: Block A helper: cash flows (t=0..5) per price x multiple | AS4: Block F helper: cash flows per price x op case (base financing)
B5: Block A: IRR - offer price (rows) x exit multiple (columns), running operating & financing case, exit Y5 | AL5: =-($C$7*LBO!$D$23*(1+LBO!$D$39)+LBO!$D$84) -> -160.26926 | AM5: =LBO!I$245 -> 0 | AN5: =LBO!J$245 -> 0.45470337 | AO5: =LBO!K$245 -> 39.187678 | AP5: =LBO!L$245 -> 36.005311 | AQ5: =LBO!M$245+(LBO!$M$238*E$6*(1-LBO!$D$44)-LBO!$M$155+LBO!$M$146) -> 210.66264 | AS5: =-($C$91*LBO!$D$23*(1+LBO!$D$39)+$Y$31) -> -166.01077 | AT5: =$Z$31 -> 0 | AU5: =$AA$31 -> 0 | AV5: =$AB$31 -> 12.284322 | AW5: =$AC$31 -> 15.070769 | AX5: =$AD$31+$R$31 -> 87.552596
C6: Offer (A$/sh) | premium | E6: 3 | F6: 4 | G6: 5 | H6: 6 | I6: 7 | J6: 8 | K6: 9 | AL6: =-($C$7*LBO!$D$23*(1+LBO!$D$39)+LBO!$D$84) -> -160.26926 | AM6: =LBO!I$245 -> 0 | AN6: =LBO!J$245 -> 0.45470337 | AO6: =LBO!K$245 -> 39.187678 | AP6: =LBO!L$245 -> 36.005311 | AQ6: =LBO!M$245+(LBO!$M$238*F$6*(1-LBO!$D$44)-LBO!$M$155+LBO!$M$146) -> 256.32633 | AS6: =-($C$91*LBO!$D$23*(1+LBO!$D$39)+$Y$32) -> -165.62566 | AT6: =$Z$32 -> 0 | AU6: =$AA$32 -> 0 | AV6: =$AB$32 -> 29.309743 | AW6: =$AC$32 -> 26.414201 | AX6: =$AD$32+$R$32 -> 194.29904
C7: 9 | D7: =C7/LBO!$D$18-1 -> 0.09223301 | E7: =IF(-AL5<=0,"n.m.",IFERROR(IRR(AL5:AQ5,0.15),IFERROR(IRR(AL5:AQ5,-0.2),IFERROR(IRR(AL5:AQ5,-0.6),-1)))) -> 0.13566357 | F7: =IF(-AL6<=0,"n.m.",IFERROR(IRR(AL6:AQ6,0.15),IFERROR(IRR(AL6:AQ6,-0.2),IFERROR(IRR(AL6:AQ6,-0.6),-1)))) -> 0.17104952 | G7: =IF(-AL7<=0,"n.m.",IFERROR(IRR(AL7:AQ7,0.15),IFERROR(IRR(AL7:AQ7,-0.2),IFERROR(IRR(AL7:AQ7,-0.6),-1)))) -> 0.2023509 | H7: =IF(-AL8<=0,"n.m.",IFERROR(IRR(AL8:AQ8,0.15),IFERROR(IRR(AL8:AQ8,-0.2),IFERROR(IRR(AL8:AQ8,-0.6),-1)))) -> 0.23050933 | I7: =IF(-AL9<=0,"n.m.",IFERROR(IRR(AL9:AQ9,0.15),IFERROR(IRR(AL9:AQ9,-0.2),IFERROR(IRR(AL9:AQ9,-0.6),-1)))) -> 0.25616485 | J7: =IF(-AL10<=0,"n.m.",IFERROR(IRR(AL10:AQ10,0.15),IFERROR(IRR(AL10:AQ10,-0.2),IFERROR(IRR(AL10:AQ10,-0.6),-1)))) -> 0.27977413 | K7: =IF(-AL11<=0,"n.m.",IFERROR(IRR(AL11:AQ11,0.15),IFERROR(IRR(AL11:AQ11,-0.2),IFERROR(IRR(AL11:AQ11,-0.6),-1)))) -> 0.30167535 | AL7: =-($C$7*LBO!$D$23*(1+LBO!$D$39)+LBO!$D$84) -> -160.26926 | AM7: =LBO!I$245 -> 0 | AN7: =LBO!J$245 -> 0.45470337 | AO7: =LBO!K$245 -> 39.187678 | AP7: =LBO!L$245 -> 36.005311 | AQ7: =LBO!M$245+(LBO!$M$238*G$6*(1-LBO!$D$44)-LBO!$M$155+LBO!$M$146) -> 301.99003 | AS7: =-($C$91*LBO!$D$23*(1+LBO!$D$39)+$Y$33) -> -160.26926 | AT7: =$Z$33 -> 0 | AU7: =$AA$33 -> 0.45470337 | AV7: =$AB$33 -> 39.187678 | AW7: =$AC$33 -> 36.005311 | AX7: =$AD$33+$R$33 -> 324.82188
C8: 9.5 | D8: =C8/LBO!$D$18-1 -> 0.15291262 | E8: =IF(-AL12<=0,"n.m.",IFERROR(IRR(AL12:AQ12,0.15),IFERROR(IRR(AL12:AQ12,-0.2),IFERROR(IRR(AL12:AQ12,-0.6),-1)))) -> 0.098579018 | F8: =IF(-AL13<=0,"n.m.",IFERROR(IRR(AL13:AQ13,0.15),IFERROR(IRR(AL13:AQ13,-0.2),IFERROR(IRR(AL13:AQ13,-0.6),-1)))) -> 0.13317656 | G8: =IF(-AL14<=0,"n.m.",IFERROR(IRR(AL14:AQ14,0.15),IFERROR(IRR(AL14:AQ14,-0.2),IFERROR(IRR(AL14:AQ14,-0.6),-1)))) -> 0.16375492 | H8: =IF(-AL15<=0,"n.m.",IFERROR(IRR(AL15:AQ15,0.15),IFERROR(IRR(AL15:AQ15,-0.2),IFERROR(IRR(AL15:AQ15,-0.6),-1)))) -> 0.1912453 | I8: =IF(-AL16<=0,"n.m.",IFERROR(IRR(AL16:AQ16,0.15),IFERROR(IRR(AL16:AQ16,-0.2),IFERROR(IRR(AL16:AQ16,-0.6),-1)))) -> 0.21627945 | J8: =IF(-AL17<=0,"n.m.",IFERROR(IRR(AL17:AQ17,0.15),IFERROR(IRR(AL17:AQ17,-0.2),IFERROR(IRR(AL17:AQ17,-0.6),-1)))) -> 0.23930735 | K8: =IF(-AL18<=0,"n.m.",IFERROR(IRR(AL18:AQ18,0.15),IFERROR(IRR(AL18:AQ18,-0.2),IFERROR(IRR(AL18:AQ18,-0.6),-1)))) -> 0.2606619 | AL8: =-($C$7*LBO!$D$23*(1+LBO!$D$39)+LBO!$D$84) -> -160.26926 | AM8: =LBO!I$245 -> 0 | AN8: =LBO!J$245 -> 0.45470337 | AO8: =LBO!K$245 -> 39.187678 | AP8: =LBO!L$245 -> 36.005311 | AQ8: =LBO!M$245+(LBO!$M$238*H$6*(1-LBO!$D$44)-LBO!$M$155+LBO!$M$146) -> 347.65372 | AS8: =-($C$91*LBO!$D$23*(1+LBO!$D$39)+$Y$34) -> -159.88415 | AT8: =$Z$34 -> 0 | AU8: =$AA$34 -> 9.3619617 | AV8: =$AB$34 -> 48.806138 | AW8: =$AC$34 -> 49.690811 | AX8: =$AD$34+$R$34 -> 579.07917
C9: 10 | D9: =C9/LBO!$D$18-1 -> 0.21359223 | E9: =IF(-AL19<=0,"n.m.",IFERROR(IRR(AL19:AQ19,0.15),IFERROR(IRR(AL19:AQ19,-0.2),IFERROR(IRR(AL19:AQ19,-0.6),-1)))) -> 0.06745946 | F9: =IF(-AL20<=0,"n.m.",IFERROR(IRR(AL20:AQ20,0.15),IFERROR(IRR(AL20:AQ20,-0.2),IFERROR(IRR(AL20:AQ20,-0.6),-1)))) -> 0.10137617 | G9: =IF(-AL21<=0,"n.m.",IFERROR(IRR(AL21:AQ21,0.15),IFERROR(IRR(AL21:AQ21,-0.2),IFERROR(IRR(AL21:AQ21,-0.6),-1)))) -> 0.13133186 | H9: =IF(-AL22<=0,"n.m.",IFERROR(IRR(AL22:AQ22,0.15),IFERROR(IRR(AL22:AQ22,-0.2),IFERROR(IRR(AL22:AQ22,-0.6),-1)))) -> 0.15824811 | I9: =IF(-AL23<=0,"n.m.",IFERROR(IRR(AL23:AQ23,0.15),IFERROR(IRR(AL23:AQ23,-0.2),IFERROR(IRR(AL23:AQ23,-0.6),-1)))) -> 0.18274907 | J9: =IF(-AL24<=0,"n.m.",IFERROR(IRR(AL24:AQ24,0.15),IFERROR(IRR(AL24:AQ24,-0.2),IFERROR(IRR(AL24:AQ24,-0.6),-1)))) -> 0.20527876 | K9: =IF(-AL25<=0,"n.m.",IFERROR(IRR(AL25:AQ25,0.15),IFERROR(IRR(AL25:AQ25,-0.2),IFERROR(IRR(AL25:AQ25,-0.6),-1)))) -> 0.22616529 | AL9: =-($C$7*LBO!$D$23*(1+LBO!$D$39)+LBO!$D$84) -> -160.26926 | AM9: =LBO!I$245 -> 0 | AN9: =LBO!J$245 -> 0.45470337 | AO9: =LBO!K$245 -> 39.187678 | AP9: =LBO!L$245 -> 36.005311 | AQ9: =LBO!M$245+(LBO!$M$238*I$6*(1-LBO!$D$44)-LBO!$M$155+LBO!$M$146) -> 393.31742 | AS9: =-($C$91*LBO!$D$23*(1+LBO!$D$39)+$Y$35) -> -159.88415 | AT9: =$Z$35 -> 0 | AU9: =$AA$35 -> 0 | AV9: =$AB$35 -> 25.370613 | AW9: =$AC$35 -> 47.650811 | AX9: =$AD$35+$R$35 -> 887.97669
C10: 10.5 | D10: =C10/LBO!$D$18-1 -> 0.27427184 | E10: =IF(-AL26<=0,"n.m.",IFERROR(IRR(AL26:AQ26,0.15),IFERROR(IRR(AL26:AQ26,-0.2),IFERROR(IRR(AL26:AQ26,-0.6),-1)))) -> 0.040766831 | F10: =IF(-AL27<=0,"n.m.",IFERROR(IRR(AL27:AQ27,0.15),IFERROR(IRR(AL27:AQ27,-0.2),IFERROR(IRR(AL27:AQ27,-0.6),-1)))) -> 0.074085445 | G10: =IF(-AL28<=0,"n.m.",IFERROR(IRR(AL28:AQ28,0.15),IFERROR(IRR(AL28:AQ28,-0.2),IFERROR(IRR(AL28:AQ28,-0.6),-1)))) -> 0.1034954 | H10: =IF(-AL29<=0,"n.m.",IFERROR(IRR(AL29:AQ29,0.15),IFERROR(IRR(AL29:AQ29,-0.2),IFERROR(IRR(AL29:AQ29,-0.6),-1)))) -> 0.12990929 | I10: =IF(-AL30<=0,"n.m.",IFERROR(IRR(AL30:AQ30,0.15),IFERROR(IRR(AL30:AQ30,-0.2),IFERROR(IRR(AL30:AQ30,-0.6),-1)))) -> 0.15394433 | J10: =IF(-AL31<=0,"n.m.",IFERROR(IRR(AL31:AQ31,0.15),IFERROR(IRR(AL31:AQ31,-0.2),IFERROR(IRR(AL31:AQ31,-0.6),-1)))) -> 0.17603911 | K10: =IF(-AL32<=0,"n.m.",IFERROR(IRR(AL32:AQ32,0.15),IFERROR(IRR(AL32:AQ32,-0.2),IFERROR(IRR(AL32:AQ32,-0.6),-1)))) -> 0.19651746 | AL10: =-($C$7*LBO!$D$23*(1+LBO!$D$39)+LBO!$D$84) -> -160.26926 | AM10: =LBO!I$245 -> 0 | AN10: =LBO!J$245 -> 0.45470337 | AO10: =LBO!K$245 -> 39.187678 | AP10: =LBO!L$245 -> 36.005311 | AQ10: =LBO!M$245+(LBO!$M$238*J$6*(1-LBO!$D$44)-LBO!$M$155+LBO!$M$146) -> 438.98111 | AS10: =-($C$92*LBO!$D$23*(1+LBO!$D$39)+$Y$31) -> -192.04762 | AT10: =$Z$31 -> 0 | AU10: =$AA$31 -> 0 | AV10: =$AB$31 -> 12.284322 | AW10: =$AC$31 -> 15.070769 | AX10: =$AD$31+$R$31 -> 87.552596
C11: 11 | D11: =C11/LBO!$D$18-1 -> 0.33495146 | E11: =IF(-AL33<=0,"n.m.",IFERROR(IRR(AL33:AQ33,0.15),IFERROR(IRR(AL33:AQ33,-0.2),IFERROR(IRR(AL33:AQ33,-0.6),-1)))) -> 0.017477761 | F11: =IF(-AL34<=0,"n.m.",IFERROR(IRR(AL34:AQ34,0.15),IFERROR(IRR(AL34:AQ34,-0.2),IFERROR(IRR(AL34:AQ34,-0.6),-1)))) -> 0.050263837 | G11: =IF(-AL35<=0,"n.m.",IFERROR(IRR(AL35:AQ35,0.15),IFERROR(IRR(AL35:AQ35,-0.2),IFERROR(IRR(AL35:AQ35,-0.6),-1)))) -> 0.079188802 | H11: =IF(-AL36<=0,"n.m.",IFERROR(IRR(AL36:AQ36,0.15),IFERROR(IRR(AL36:AQ36,-0.2),IFERROR(IRR(AL36:AQ36,-0.6),-1)))) -> 0.1051569 | I11: =IF(-AL37<=0,"n.m.",IFERROR(IRR(AL37:AQ37,0.15),IFERROR(IRR(AL37:AQ37,-0.2),IFERROR(IRR(AL37:AQ37,-0.6),-1)))) -> 0.12877893 | J11: =IF(-AL38<=0,"n.m.",IFERROR(IRR(AL38:AQ38,0.15),IFERROR(IRR(AL38:AQ38,-0.2),IFERROR(IRR(AL38:AQ38,-0.6),-1)))) -> 0.15048854 | K11: =IF(-AL39<=0,"n.m.",IFERROR(IRR(AL39:AQ39,0.15),IFERROR(IRR(AL39:AQ39,-0.2),IFERROR(IRR(AL39:AQ39,-0.6),-1)))) -> 0.17060564 | AL11: =-($C$7*LBO!$D$23*(1+LBO!$D$39)+LBO!$D$84) -> -160.26926 | AM11: =LBO!I$245 -> 0 | AN11: =LBO!J$245 -> 0.45470337 | AO11: =LBO!K$245 -> 39.187678 | AP11: =LBO!L$245 -> 36.005311 | AQ11: =LBO!M$245+(LBO!$M$238*K$6*(1-LBO!$D$44)-LBO!$M$155+LBO!$M$146) -> 484.64481 | AS11: =-($C$92*LBO!$D$23*(1+LBO!$D$39)+$Y$32) -> -191.66251 | AT11: =$Z$32 -> 0 | AU11: =$AA$32 -> 0 | AV11: =$AB$32 -> 29.309743 | AW11: =$AC$32 -> 26.414201 | AX11: =$AD$32+$R$32 -> 194.29904
C12: 11.5 | D12: =C12/LBO!$D$18-1 -> 0.39563107 | E12: =IF(-AL40<=0,"n.m.",IFERROR(IRR(AL40:AQ40,0.15),IFERROR(IRR(AL40:AQ40,-0.2),IFERROR(IRR(AL40:AQ40,-0.6),-1)))) -> -0.003120776 | F12: =IF(-AL41<=0,"n.m.",IFERROR(IRR(AL41:AQ41,0.15),IFERROR(IRR(AL41:AQ41,-0.2),IFERROR(IRR(AL41:AQ41,-0.6),-1)))) -> 0.029185929 | G12: =IF(-AL42<=0,"n.m.",IFERROR(IRR(AL42:AQ42,0.15),IFERROR(IRR(AL42:AQ42,-0.2),IFERROR(IRR(AL42:AQ42,-0.6),-1)))) -> 0.057675048 | H12: =IF(-AL43<=0,"n.m.",IFERROR(IRR(AL43:AQ43,0.15),IFERROR(IRR(AL43:AQ43,-0.2),IFERROR(IRR(AL43:AQ43,-0.6),-1)))) -> 0.083243012 | I12: =IF(-AL44<=0,"n.m.",IFERROR(IRR(AL44:AQ44,0.15),IFERROR(IRR(AL44:AQ44,-0.2),IFERROR(IRR(AL44:AQ44,-0.6),-1)))) -> 0.1064947 | J12: =IF(-AL45<=0,"n.m.",IFERROR(IRR(AL45:AQ45,0.15),IFERROR(IRR(AL45:AQ45,-0.2),IFERROR(IRR(AL45:AQ45,-0.6),-1)))) -> 0.12785918 | K12: =IF(-AL46<=0,"n.m.",IFERROR(IRR(AL46:AQ46,0.15),IFERROR(IRR(AL46:AQ46,-0.2),IFERROR(IRR(AL46:AQ46,-0.6),-1)))) -> 0.14765279 | AL12: =-($C$8*LBO!$D$23*(1+LBO!$D$39)+LBO!$D$84) -> -186.30611 | AM12: =LBO!I$245 -> 0 | AN12: =LBO!J$245 -> 0.45470337 | AO12: =LBO!K$245 -> 39.187678 | AP12: =LBO!L$245 -> 36.005311 | AQ12: =LBO!M$245+(LBO!$M$238*E$6*(1-LBO!$D$44)-LBO!$M$155+LBO!$M$146) -> 210.66264 | AS12: =-($C$92*LBO!$D$23*(1+LBO!$D$39)+$Y$33) -> -186.30611 | AT12: =$Z$33 -> 0 | AU12: =$AA$33 -> 0.45470337 | AV12: =$AB$33 -> 39.187678 | AW12: =$AC$33 -> 36.005311 | AX12: =$AD$33+$R$33 -> 324.82188
C13: 12 | D13: =C13/LBO!$D$18-1 -> 0.45631068 | E13: =IF(-AL47<=0,"n.m.",IFERROR(IRR(AL47:AQ47,0.15),IFERROR(IRR(AL47:AQ47,-0.2),IFERROR(IRR(AL47:AQ47,-0.6),-1)))) -> -0.021544106 | F13: =IF(-AL48<=0,"n.m.",IFERROR(IRR(AL48:AQ48,0.15),IFERROR(IRR(AL48:AQ48,-0.2),IFERROR(IRR(AL48:AQ48,-0.6),-1)))) -> 0.010327178 | G13: =IF(-AL49<=0,"n.m.",IFERROR(IRR(AL49:AQ49,0.15),IFERROR(IRR(AL49:AQ49,-0.2),IFERROR(IRR(AL49:AQ49,-0.6),-1)))) -> 0.038420984 | H13: =IF(-AL50<=0,"n.m.",IFERROR(IRR(AL50:AQ50,0.15),IFERROR(IRR(AL50:AQ50,-0.2),IFERROR(IRR(AL50:AQ50,-0.6),-1)))) -> 0.063626415 | I13: =IF(-AL51<=0,"n.m.",IFERROR(IRR(AL51:AQ51,0.15),IFERROR(IRR(AL51:AQ51,-0.2),IFERROR(IRR(AL51:AQ51,-0.6),-1)))) -> 0.086542833 | J13: =IF(-AL52<=0,"n.m.",IFERROR(IRR(AL52:AQ52,0.15),IFERROR(IRR(AL52:AQ52,-0.2),IFERROR(IRR(AL52:AQ52,-0.6),-1)))) -> 0.10759509 | K13: =IF(-AL53<=0,"n.m.",IFERROR(IRR(AL53:AQ53,0.15),IFERROR(IRR(AL53:AQ53,-0.2),IFERROR(IRR(AL53:AQ53,-0.6),-1)))) -> 0.12709622 | AL13: =-($C$8*LBO!$D$23*(1+LBO!$D$39)+LBO!$D$84) -> -186.30611 | AM13: =LBO!I$245 -> 0 | AN13: =LBO!J$245 -> 0.45470337 | AO13: =LBO!K$245 -> 39.187678 | AP13: =LBO!L$245 -> 36.005311 | AQ13: =LBO!M$245+(LBO!$M$238*F$6*(1-LBO!$D$44)-LBO!$M$155+LBO!$M$146) -> 256.32633 | AS13: =-($C$92*LBO!$D$23*(1+LBO!$D$39)+$Y$34) -> -185.921 | AT13: =$Z$34 -> 0 | AU13: =$AA$34 -> 9.3619617 | AV13: =$AB$34 -> 48.806138 | AW13: =$AC$34 -> 49.690811 | AX13: =$AD$34+$R$34 -> 579.07917
C14: 12.5 | D14: =C14/LBO!$D$18-1 -> 0.51699029 | E14: =IF(-AL54<=0,"n.m.",IFERROR(IRR(AL54:AQ54,0.15),IFERROR(IRR(AL54:AQ54,-0.2),IFERROR(IRR(AL54:AQ54,-0.6),-1)))) -> -0.038175953 | F14: =IF(-AL55<=0,"n.m.",IFERROR(IRR(AL55:AQ55,0.15),IFERROR(IRR(AL55:AQ55,-0.2),IFERROR(IRR(AL55:AQ55,-0.6),-1)))) -> -0.0067031764 | G14: =IF(-AL56<=0,"n.m.",IFERROR(IRR(AL56:AQ56,0.15),IFERROR(IRR(AL56:AQ56,-0.2),IFERROR(IRR(AL56:AQ56,-0.6),-1)))) -> 0.021029291 | H14: =IF(-AL57<=0,"n.m.",IFERROR(IRR(AL57:AQ57,0.15),IFERROR(IRR(AL57:AQ57,-0.2),IFERROR(IRR(AL57:AQ57,-0.6),-1)))) -> 0.045903663 | I14: =IF(-AL58<=0,"n.m.",IFERROR(IRR(AL58:AQ58,0.15),IFERROR(IRR(AL58:AQ58,-0.2),IFERROR(IRR(AL58:AQ58,-0.6),-1)))) -> 0.068514147 | J14: =IF(-AL59<=0,"n.m.",IFERROR(IRR(AL59:AQ59,0.15),IFERROR(IRR(AL59:AQ59,-0.2),IFERROR(IRR(AL59:AQ59,-0.6),-1)))) -> 0.089281662 | K14: =IF(-AL60<=0,"n.m.",IFERROR(IRR(AL60:AQ60,0.15),IFERROR(IRR(AL60:AQ60,-0.2),IFERROR(IRR(AL60:AQ60,-0.6),-1)))) -> 0.10851618 | AL14: =-($C$8*LBO!$D$23*(1+LBO!$D$39)+LBO!$D$84) -> -186.30611 | AM14: =LBO!I$245 -> 0 | AN14: =LBO!J$245 -> 0.45470337 | AO14: =LBO!K$245 -> 39.187678 | AP14: =LBO!L$245 -> 36.005311 | AQ14: =LBO!M$245+(LBO!$M$238*G$6*(1-LBO!$D$44)-LBO!$M$155+LBO!$M$146) -> 301.99003 | AS14: =-($C$92*LBO!$D$23*(1+LBO!$D$39)+$Y$35) -> -185.921 | AT14: =$Z$35 -> 0 | AU14: =$AA$35 -> 0 | AV14: =$AB$35 -> 25.370613 | AW14: =$AC$35 -> 47.650811 | AX14: =$AD$35+$R$35 -> 887.97669
C15: 13 | D15: =C15/LBO!$D$18-1 -> 0.5776699 | E15: =IF(-AL61<=0,"n.m.",IFERROR(IRR(AL61:AQ61,0.15),IFERROR(IRR(AL61:AQ61,-0.2),IFERROR(IRR(AL61:AQ61,-0.6),-1)))) -> -0.053309212 | F15: =IF(-AL62<=0,"n.m.",IFERROR(IRR(AL62:AQ62,0.15),IFERROR(IRR(AL62:AQ62,-0.2),IFERROR(IRR(AL62:AQ62,-0.6),-1)))) -> -0.022203522 | G15: =IF(-AL63<=0,"n.m.",IFERROR(IRR(AL63:AQ63,0.15),IFERROR(IRR(AL63:AQ63,-0.2),IFERROR(IRR(AL63:AQ63,-0.6),-1)))) -> 0.0051964775 | H15: =IF(-AL64<=0,"n.m.",IFERROR(IRR(AL64:AQ64,0.15),IFERROR(IRR(AL64:AQ64,-0.2),IFERROR(IRR(AL64:AQ64,-0.6),-1)))) -> 0.029766499 | I15: =IF(-AL65<=0,"n.m.",IFERROR(IRR(AL65:AQ65,0.15),IFERROR(IRR(AL65:AQ65,-0.2),IFERROR(IRR(AL65:AQ65,-0.6),-1)))) -> 0.052095915 | J15: =IF(-AL66<=0,"n.m.",IFERROR(IRR(AL66:AQ66,0.15),IFERROR(IRR(AL66:AQ66,-0.2),IFERROR(IRR(AL66:AQ66,-0.6),-1)))) -> 0.072601972 | K15: =IF(-AL67<=0,"n.m.",IFERROR(IRR(AL67:AQ67,0.15),IFERROR(IRR(AL67:AQ67,-0.2),IFERROR(IRR(AL67:AQ67,-0.6),-1)))) -> 0.091591789 | AL15: =-($C$8*LBO!$D$23*(1+LBO!$D$39)+LBO!$D$84) -> -186.30611 | AM15: =LBO!I$245 -> 0 | AN15: =LBO!J$245 -> 0.45470337 | AO15: =LBO!K$245 -> 39.187678 | AP15: =LBO!L$245 -> 36.005311 | AQ15: =LBO!M$245+(LBO!$M$238*H$6*(1-LBO!$D$44)-LBO!$M$155+LBO!$M$146) -> 347.65372 | AS15: =-($C$93*LBO!$D$23*(1+LBO!$D$39)+$Y$31) -> -218.08447 | AT15: =$Z$31 -> 0 | AU15: =$AA$31 -> 0 | AV15: =$AB$31 -> 12.284322 | AW15: =$AC$31 -> 15.070769 | AX15: =$AD$31+$R$31 -> 87.552596
AL16: =-($C$8*LBO!$D$23*(1+LBO!$D$39)+LBO!$D$84) -> -186.30611 | AM16: =LBO!I$245 -> 0 | AN16: =LBO!J$245 -> 0.45470337 | AO16: =LBO!K$245 -> 39.187678 | AP16: =LBO!L$245 -> 36.005311 | AQ16: =LBO!M$245+(LBO!$M$238*I$6*(1-LBO!$D$44)-LBO!$M$155+LBO!$M$146) -> 393.31742 | AS16: =-($C$93*LBO!$D$23*(1+LBO!$D$39)+$Y$32) -> -217.69936 | AT16: =$Z$32 -> 0 | AU16: =$AA$32 -> 0 | AV16: =$AB$32 -> 29.309743 | AW16: =$AC$32 -> 26.414201 | AX16: =$AD$32+$R$32 -> 194.29904
B17: Block B: MoIC - offer price x exit multiple (running case, exit Y5) | AL17: =-($C$8*LBO!$D$23*(1+LBO!$D$39)+LBO!$D$84) -> -186.30611 | AM17: =LBO!I$245 -> 0 | AN17: =LBO!J$245 -> 0.45470337 | AO17: =LBO!K$245 -> 39.187678 | AP17: =LBO!L$245 -> 36.005311 | AQ17: =LBO!M$245+(LBO!$M$238*J$6*(1-LBO!$D$44)-LBO!$M$155+LBO!$M$146) -> 438.98111 | AS17: =-($C$93*LBO!$D$23*(1+LBO!$D$39)+$Y$33) -> -212.34296 | AT17: =$Z$33 -> 0 | AU17: =$AA$33 -> 0.45470337 | AV17: =$AB$33 -> 39.187678 | AW17: =$AC$33 -> 36.005311 | AX17: =$AD$33+$R$33 -> 324.82188
E18: 3 | F18: 4 | G18: 5 | H18: 6 | I18: 7 | J18: 8 | K18: 9 | AL18: =-($C$8*LBO!$D$23*(1+LBO!$D$39)+LBO!$D$84) -> -186.30611 | AM18: =LBO!I$245 -> 0 | AN18: =LBO!J$245 -> 0.45470337 | AO18: =LBO!K$245 -> 39.187678 | AP18: =LBO!L$245 -> 36.005311 | AQ18: =LBO!M$245+(LBO!$M$238*K$6*(1-LBO!$D$44)-LBO!$M$155+LBO!$M$146) -> 484.64481 | AS18: =-($C$93*LBO!$D$23*(1+LBO!$D$39)+$Y$34) -> -211.95785 | AT18: =$Z$34 -> 0 | AU18: =$AA$34 -> 9.3619617 | AV18: =$AB$34 -> 48.806138 | AW18: =$AC$34 -> 49.690811 | AX18: =$AD$34+$R$34 -> 579.07917
C19: 9 | D19: =C19/LBO!$D$18-1 -> 0.09223301 | E19: =IF(-AL5<=0,"n.m.",(SUM(AM5:AQ5))/(-AL5)) -> 1.7864332 | F19: =IF(-AL6<=0,"n.m.",(SUM(AM6:AQ6))/(-AL6)) -> 2.0713518 | G19: =IF(-AL7<=0,"n.m.",(SUM(AM7:AQ7))/(-AL7)) -> 2.3562704 | H19: =IF(-AL8<=0,"n.m.",(SUM(AM8:AQ8))/(-AL8)) -> 2.641189 | I19: =IF(-AL9<=0,"n.m.",(SUM(AM9:AQ9))/(-AL9)) -> 2.9261076 | J19: =IF(-AL10<=0,"n.m.",(SUM(AM10:AQ10))/(-AL10)) -> 3.2110262 | K19: =IF(-AL11<=0,"n.m.",(SUM(AM11:AQ11))/(-AL11)) -> 3.4959448 | AL19: =-($C$9*LBO!$D$23*(1+LBO!$D$39)+LBO!$D$84) -> -212.34296 | AM19: =LBO!I$245 -> 0 | AN19: =LBO!J$245 -> 0.45470337 | AO19: =LBO!K$245 -> 39.187678 | AP19: =LBO!L$245 -> 36.005311 | AQ19: =LBO!M$245+(LBO!$M$238*E$6*(1-LBO!$D$44)-LBO!$M$155+LBO!$M$146) -> 210.66264 | AS19: =-($C$93*LBO!$D$23*(1+LBO!$D$39)+$Y$35) -> -211.95785 | AT19: =$Z$35 -> 0 | AU19: =$AA$35 -> 0 | AV19: =$AB$35 -> 25.370613 | AW19: =$AC$35 -> 47.650811 | AX19: =$AD$35+$R$35 -> 887.97669
C20: 9.5 | D20: =C20/LBO!$D$18-1 -> 0.15291262 | E20: =IF(-AL12<=0,"n.m.",(SUM(AM12:AQ12))/(-AL12)) -> 1.5367737 | F20: =IF(-AL13<=0,"n.m.",(SUM(AM13:AQ13))/(-AL13)) -> 1.781874 | G20: =IF(-AL14<=0,"n.m.",(SUM(AM14:AQ14))/(-AL14)) -> 2.0269744 | H20: =IF(-AL15<=0,"n.m.",(SUM(AM15:AQ15))/(-AL15)) -> 2.2720748 | I20: =IF(-AL16<=0,"n.m.",(SUM(AM16:AQ16))/(-AL16)) -> 2.5171751 | J20: =IF(-AL17<=0,"n.m.",(SUM(AM17:AQ17))/(-AL17)) -> 2.7622755 | K20: =IF(-AL18<=0,"n.m.",(SUM(AM18:AQ18))/(-AL18)) -> 3.0073758 | AL20: =-($C$9*LBO!$D$23*(1+LBO!$D$39)+LBO!$D$84) -> -212.34296 | AM20: =LBO!I$245 -> 0 | AN20: =LBO!J$245 -> 0.45470337 | AO20: =LBO!K$245 -> 39.187678 | AP20: =LBO!L$245 -> 36.005311 | AQ20: =LBO!M$245+(LBO!$M$238*F$6*(1-LBO!$D$44)-LBO!$M$155+LBO!$M$146) -> 256.32633 | AS20: =-($C$94*LBO!$D$23*(1+LBO!$D$39)+$Y$31) -> -244.12132 | AT20: =$Z$31 -> 0 | AU20: =$AA$31 -> 0 | AV20: =$AB$31 -> 12.284322 | AW20: =$AC$31 -> 15.070769 | AX20: =$AD$31+$R$31 -> 87.552596
C21: 10 | D21: =C21/LBO!$D$18-1 -> 0.21359223 | E21: =IF(-AL19<=0,"n.m.",(SUM(AM19:AQ19))/(-AL19)) -> 1.3483391 | F21: =IF(-AL20<=0,"n.m.",(SUM(AM20:AQ20))/(-AL20)) -> 1.563386 | G21: =IF(-AL21<=0,"n.m.",(SUM(AM21:AQ21))/(-AL21)) -> 1.7784329 | H21: =IF(-AL22<=0,"n.m.",(SUM(AM22:AQ22))/(-AL22)) -> 1.9934798 | I21: =IF(-AL23<=0,"n.m.",(SUM(AM23:AQ23))/(-AL23)) -> 2.2085267 | J21: =IF(-AL24<=0,"n.m.",(SUM(AM24:AQ24))/(-AL24)) -> 2.4235736 | K21: =IF(-AL25<=0,"n.m.",(SUM(AM25:AQ25))/(-AL25)) -> 2.6386205 | AL21: =-($C$9*LBO!$D$23*(1+LBO!$D$39)+LBO!$D$84) -> -212.34296 | AM21: =LBO!I$245 -> 0 | AN21: =LBO!J$245 -> 0.45470337 | AO21: =LBO!K$245 -> 39.187678 | AP21: =LBO!L$245 -> 36.005311 | AQ21: =LBO!M$245+(LBO!$M$238*G$6*(1-LBO!$D$44)-LBO!$M$155+LBO!$M$146) -> 301.99003 | AS21: =-($C$94*LBO!$D$23*(1+LBO!$D$39)+$Y$32) -> -243.73621 | AT21: =$Z$32 -> 0 | AU21: =$AA$32 -> 0 | AV21: =$AB$32 -> 29.309743 | AW21: =$AC$32 -> 26.414201 | AX21: =$AD$32+$R$32 -> 194.29904
C22: 10.5 | D22: =C22/LBO!$D$18-1 -> 0.27427184 | E22: =IF(-AL26<=0,"n.m.",(SUM(AM26:AQ26))/(-AL26)) -> 1.2010679 | F22: =IF(-AL27<=0,"n.m.",(SUM(AM27:AQ27))/(-AL27)) -> 1.3926264 | G22: =IF(-AL28<=0,"n.m.",(SUM(AM28:AQ28))/(-AL28)) -> 1.584185 | H22: =IF(-AL29<=0,"n.m.",(SUM(AM29:AQ29))/(-AL29)) -> 1.7757436 | I22: =IF(-AL30<=0,"n.m.",(SUM(AM30:AQ30))/(-AL30)) -> 1.9673021 | J22: =IF(-AL31<=0,"n.m.",(SUM(AM31:AQ31))/(-AL31)) -> 2.1588607 | K22: =IF(-AL32<=0,"n.m.",(SUM(AM32:AQ32))/(-AL32)) -> 2.3504193 | AL22: =-($C$9*LBO!$D$23*(1+LBO!$D$39)+LBO!$D$84) -> -212.34296 | AM22: =LBO!I$245 -> 0 | AN22: =LBO!J$245 -> 0.45470337 | AO22: =LBO!K$245 -> 39.187678 | AP22: =LBO!L$245 -> 36.005311 | AQ22: =LBO!M$245+(LBO!$M$238*H$6*(1-LBO!$D$44)-LBO!$M$155+LBO!$M$146) -> 347.65372 | AS22: =-($C$94*LBO!$D$23*(1+LBO!$D$39)+$Y$33) -> -238.37981 | AT22: =$Z$33 -> 0 | AU22: =$AA$33 -> 0.45470337 | AV22: =$AB$33 -> 39.187678 | AW22: =$AC$33 -> 36.005311 | AX22: =$AD$33+$R$33 -> 324.82188
C23: 11 | D23: =C23/LBO!$D$18-1 -> 0.33495146 | E23: =IF(-AL33<=0,"n.m.",(SUM(AM33:AQ33))/(-AL33)) -> 1.0827999 | F23: =IF(-AL34<=0,"n.m.",(SUM(AM34:AQ34))/(-AL34)) -> 1.2554959 | G23: =IF(-AL35<=0,"n.m.",(SUM(AM35:AQ35))/(-AL35)) -> 1.4281918 | H23: =IF(-AL36<=0,"n.m.",(SUM(AM36:AQ36))/(-AL36)) -> 1.6008878 | I23: =IF(-AL37<=0,"n.m.",(SUM(AM37:AQ37))/(-AL37)) -> 1.7735838 | J23: =IF(-AL38<=0,"n.m.",(SUM(AM38:AQ38))/(-AL38)) -> 1.9462798 | K23: =IF(-AL39<=0,"n.m.",(SUM(AM39:AQ39))/(-AL39)) -> 2.1189758 | AL23: =-($C$9*LBO!$D$23*(1+LBO!$D$39)+LBO!$D$84) -> -212.34296 | AM23: =LBO!I$245 -> 0 | AN23: =LBO!J$245 -> 0.45470337 | AO23: =LBO!K$245 -> 39.187678 | AP23: =LBO!L$245 -> 36.005311 | AQ23: =LBO!M$245+(LBO!$M$238*I$6*(1-LBO!$D$44)-LBO!$M$155+LBO!$M$146) -> 393.31742 | AS23: =-($C$94*LBO!$D$23*(1+LBO!$D$39)+$Y$34) -> -237.9947 | AT23: =$Z$34 -> 0 | AU23: =$AA$34 -> 9.3619617 | AV23: =$AB$34 -> 48.806138 | AW23: =$AC$34 -> 49.690811 | AX23: =$AD$34+$R$34 -> 579.07917
C24: 11.5 | D24: =C24/LBO!$D$18-1 -> 0.39563107 | E24: =IF(-AL40<=0,"n.m.",(SUM(AM40:AQ40))/(-AL40)) -> 0.98573547 | F24: =IF(-AL41<=0,"n.m.",(SUM(AM41:AQ41))/(-AL41)) -> 1.1429506 | G24: =IF(-AL42<=0,"n.m.",(SUM(AM42:AQ42))/(-AL42)) -> 1.3001658 | H24: =IF(-AL43<=0,"n.m.",(SUM(AM43:AQ43))/(-AL43)) -> 1.4573809 | I24: =IF(-AL44<=0,"n.m.",(SUM(AM44:AQ44))/(-AL44)) -> 1.6145961 | J24: =IF(-AL45<=0,"n.m.",(SUM(AM45:AQ45))/(-AL45)) -> 1.7718113 | K24: =IF(-AL46<=0,"n.m.",(SUM(AM46:AQ46))/(-AL46)) -> 1.9290264 | AL24: =-($C$9*LBO!$D$23*(1+LBO!$D$39)+LBO!$D$84) -> -212.34296 | AM24: =LBO!I$245 -> 0 | AN24: =LBO!J$245 -> 0.45470337 | AO24: =LBO!K$245 -> 39.187678 | AP24: =LBO!L$245 -> 36.005311 | AQ24: =LBO!M$245+(LBO!$M$238*J$6*(1-LBO!$D$44)-LBO!$M$155+LBO!$M$146) -> 438.98111 | AS24: =-($C$94*LBO!$D$23*(1+LBO!$D$39)+$Y$35) -> -237.9947 | AT24: =$Z$35 -> 0 | AU24: =$AA$35 -> 0 | AV24: =$AB$35 -> 25.370613 | AW24: =$AC$35 -> 47.650811 | AX24: =$AD$35+$R$35 -> 887.97669
C25: 12 | D25: =C25/LBO!$D$18-1 -> 0.45631068 | E25: =IF(-AL47<=0,"n.m.",(SUM(AM47:AQ47))/(-AL47)) -> 0.90464154 | F25: =IF(-AL48<=0,"n.m.",(SUM(AM48:AQ48))/(-AL48)) -> 1.048923 | G25: =IF(-AL49<=0,"n.m.",(SUM(AM49:AQ49))/(-AL49)) -> 1.1932045 | H25: =IF(-AL50<=0,"n.m.",(SUM(AM50:AQ50))/(-AL50)) -> 1.337486 | I25: =IF(-AL51<=0,"n.m.",(SUM(AM51:AQ51))/(-AL51)) -> 1.4817674 | J25: =IF(-AL52<=0,"n.m.",(SUM(AM52:AQ52))/(-AL52)) -> 1.6260489 | K25: =IF(-AL53<=0,"n.m.",(SUM(AM53:AQ53))/(-AL53)) -> 1.7703304 | AL25: =-($C$9*LBO!$D$23*(1+LBO!$D$39)+LBO!$D$84) -> -212.34296 | AM25: =LBO!I$245 -> 0 | AN25: =LBO!J$245 -> 0.45470337 | AO25: =LBO!K$245 -> 39.187678 | AP25: =LBO!L$245 -> 36.005311 | AQ25: =LBO!M$245+(LBO!$M$238*K$6*(1-LBO!$D$44)-LBO!$M$155+LBO!$M$146) -> 484.64481 | AS25: =-($C$95*LBO!$D$23*(1+LBO!$D$39)+$Y$31) -> -270.15817 | AT25: =$Z$31 -> 0 | AU25: =$AA$31 -> 0 | AV25: =$AB$31 -> 12.284322 | AW25: =$AC$31 -> 15.070769 | AX25: =$AD$31+$R$31 -> 87.552596
C26: 12.5 | D26: =C26/LBO!$D$18-1 -> 0.51699029 | E26: =IF(-AL54<=0,"n.m.",(SUM(AM54:AQ54))/(-AL54)) -> 0.83587615 | F26: =IF(-AL55<=0,"n.m.",(SUM(AM55:AQ55))/(-AL55)) -> 0.96919022 | G26: =IF(-AL56<=0,"n.m.",(SUM(AM56:AQ56))/(-AL56)) -> 1.1025043 | H26: =IF(-AL57<=0,"n.m.",(SUM(AM57:AQ57))/(-AL57)) -> 1.2358184 | I26: =IF(-AL58<=0,"n.m.",(SUM(AM58:AQ58))/(-AL58)) -> 1.3691324 | J26: =IF(-AL59<=0,"n.m.",(SUM(AM59:AQ59))/(-AL59)) -> 1.5024465 | K26: =IF(-AL60<=0,"n.m.",(SUM(AM60:AQ60))/(-AL60)) -> 1.6357605 | AL26: =-($C$10*LBO!$D$23*(1+LBO!$D$39)+LBO!$D$84) -> -238.37981 | AM26: =LBO!I$245 -> 0 | AN26: =LBO!J$245 -> 0.45470337 | AO26: =LBO!K$245 -> 39.187678 | AP26: =LBO!L$245 -> 36.005311 | AQ26: =LBO!M$245+(LBO!$M$238*E$6*(1-LBO!$D$44)-LBO!$M$155+LBO!$M$146) -> 210.66264 | AS26: =-($C$95*LBO!$D$23*(1+LBO!$D$39)+$Y$32) -> -269.77306 | AT26: =$Z$32 -> 0 | AU26: =$AA$32 -> 0 | AV26: =$AB$32 -> 29.309743 | AW26: =$AC$32 -> 26.414201 | AX26: =$AD$32+$R$32 -> 194.29904
C27: 13 | D27: =C27/LBO!$D$18-1 -> 0.5776699 | E27: =IF(-AL61<=0,"n.m.",(SUM(AM61:AQ61))/(-AL61)) -> 0.7768265 | F27: =IF(-AL62<=0,"n.m.",(SUM(AM62:AQ62))/(-AL62)) -> 0.90072272 | G27: =IF(-AL63<=0,"n.m.",(SUM(AM63:AQ63))/(-AL63)) -> 1.0246189 | H27: =IF(-AL64<=0,"n.m.",(SUM(AM64:AQ64))/(-AL64)) -> 1.1485152 | I27: =IF(-AL65<=0,"n.m.",(SUM(AM65:AQ65))/(-AL65)) -> 1.2724114 | J27: =IF(-AL66<=0,"n.m.",(SUM(AM66:AQ66))/(-AL66)) -> 1.3963076 | K27: =IF(-AL67<=0,"n.m.",(SUM(AM67:AQ67))/(-AL67)) -> 1.5202038 | AL27: =-($C$10*LBO!$D$23*(1+LBO!$D$39)+LBO!$D$84) -> -238.37981 | AM27: =LBO!I$245 -> 0 | AN27: =LBO!J$245 -> 0.45470337 | AO27: =LBO!K$245 -> 39.187678 | AP27: =LBO!L$245 -> 36.005311 | AQ27: =LBO!M$245+(LBO!$M$238*F$6*(1-LBO!$D$44)-LBO!$M$155+LBO!$M$146) -> 256.32633 | AS27: =-($C$95*LBO!$D$23*(1+LBO!$D$39)+$Y$33) -> -264.41666 | AT27: =$Z$33 -> 0 | AU27: =$AA$33 -> 0.45470337 | AV27: =$AB$33 -> 39.187678 | AW27: =$AC$33 -> 36.005311 | AX27: =$AD$33+$R$33 -> 324.82188
AL28: =-($C$10*LBO!$D$23*(1+LBO!$D$39)+LBO!$D$84) -> -238.37981 | AM28: =LBO!I$245 -> 0 | AN28: =LBO!J$245 -> 0.45470337 | AO28: =LBO!K$245 -> 39.187678 | AP28: =LBO!L$245 -> 36.005311 | AQ28: =LBO!M$245+(LBO!$M$238*G$6*(1-LBO!$D$44)-LBO!$M$155+LBO!$M$146) -> 301.99003 | AS28: =-($C$95*LBO!$D$23*(1+LBO!$D$39)+$Y$34) -> -264.03155 | AT28: =$Z$34 -> 0 | AU28: =$AA$34 -> 9.3619617 | AV28: =$AB$34 -> 48.806138 | AW28: =$AC$34 -> 49.690811 | AX28: =$AD$34+$R$34 -> 579.07917
B29: Block C: case capture table (self-referencing IF: each row snapshots the model when MCASE = its case #) | AL29: =-($C$10*LBO!$D$23*(1+LBO!$D$39)+LBO!$D$84) -> -238.37981 | AM29: =LBO!I$245 -> 0 | AN29: =LBO!J$245 -> 0.45470337 | AO29: =LBO!K$245 -> 39.187678 | AP29: =LBO!L$245 -> 36.005311 | AQ29: =LBO!M$245+(LBO!$M$238*H$6*(1-LBO!$D$44)-LBO!$M$155+LBO!$M$146) -> 347.65372 | AS29: =-($C$95*LBO!$D$23*(1+LBO!$D$39)+$Y$35) -> -264.03155 | AT29: =$Z$35 -> 0 | AU29: =$AA$35 -> 0 | AV29: =$AB$35 -> 25.370613 | AW29: =$AC$35 -> 47.650811 | AX29: =$AD$35+$R$35 -> 887.97669
