Workbook

Sheet Spreads
E2: Date | F2: 46286 | K2: =+$F$2 -> 46286 | L2: 46038 | M2: =+$F$2 -> 46286 | N2: =+$F$2 -> 46286 | O2: =+$F$2 -> 46286 | P2: =+$F$2 -> 46286 | Q2: =+$F$2 -> 46286 | R2: =+$F$2 -> 46286 | S2: =+$F$2 -> 46286 | T2: =+$F$2 -> 46286 | ... X2: =+$F$2 -> 46286 | Y2: 46121 | Z2: =+$F$2 -> 46286 | AA2: =+$F$2 -> 46286 | AB2: =+$F$2 -> 46286 | AC2: =+$F$2 -> 46286 | AD2: =+$F$2 -> 46286 | AE2: =+$F$2 -> 46286 | AF2: =+$F$2 -> 46286
E3: EOY | F3: 46022
E4: Currency | F4: USD
E5: Pre-IFRS 16 toggle | F5: 1
E6: Ticker | K6: [Template] | L6: QGEN-US | M6: BIO-US | N6: NEOG-US | O6: MRVI-US | P6: BANB-CH | Q6: SFZN-CH | R6: LONN-CH | S6: 207940-KR | T6: 237690-KR | U6: ROVI-ES | V6: ERF-FR | W6: SGSN-CH | X6: BVI-FR | Y6: ITRK-GB | Z6: WAT-US | AA6: RVTY-US | AB6: TMO-US | AC6: DHR-US | AD6: A-US | AE6: 2269-HK | AF6: OXB-GB
A8: x | B8: x | E8: BASIC FACTS
E10: Company Name | G10: NAME | K10: [Template] | L10: Qiagen | M10: Bio-Rad | N10: Neogen | O10: Maravai | P10: Bachem | Q10: Siegfried | R10: Lonza | S10: Samsung Biologics | T10: ST Pharm | U10: ROVI | V10: Eurofins | W10: SGS | X10: Bureau Veritas | Y10: Intertek | Z10: Waters | AA10: Revvity | AB10: Thermo Fisher | AC10: Danaher | AD10: Agilent | AE10: Wuxi Biologics | AF10: Oxford Biomedica
E11: Spread By: | K11: n/a | L11: Hand spread (filings) | M11: Hand spread (filings) | N11: Hand spread (filings) | O11: Hand spread (filings) | P11: Hand spread (filings) | Q11: Hand spread (filings) | R11: Hand spread (filings) | S11: Hand spread (filings) | T11: Hand spread (filings) | U11: Hand spread (filings) | V11: Hand spread (filings) | W11: Hand spread (filings) | X11: Hand spread (filings) | Y11: Hand spread (filings) | Z11: Hand spread (filings) | AA11: Hand spread (filings) | AB11: Hand spread (filings) | AC11: Hand spread (filings) | AD11: Hand spread (filings) | AE11: Hand spread (filings) | AF11: Hand spread (filings)
E12: Checked By: | K12: n/a | L12: [ ] | M12: [ ] | N12: [ ] | O12: [ ] | P12: [ ] | Q12: [ ] | R12: [ ] | S12: [ ] | T12: [ ] | U12: [ ] | V12: [ ] | W12: [ ] | X12: [ ] | Y12: [ ] | Z12: [ ] | AA12: [ ] | AB12: [ ] | AC12: [ ] | AD12: [ ] | AE12: n/a | AF12: [ ]
E13: Latest Filing | K13: [ ] | L13: QIAGEN Q2-26 Quarterly Report (Form 6-K Ex.99.1 filed 7-Aug-26), quarter ended 30-Jun-26 | M13: Bio-Rad Form 10-Q, quarter ended 30-Jun-26 | N13: Neogen Form 10-K FY26 (YE 31-May-26) | O13: Maravai Form 10-Q, quarter ended 30-Jun-26 | P13: Bachem Half-Year Report 2026 (30-Jun-26, Swiss GAAP FER) | Q13: Siegfried Half-Year Report 2026 (30-Jun-26, Swiss GAAP FER) | R13: Lonza Half-Year Report 2026 (30-Jun-26, IFRS; via SGXNet) | S13: Samsung Biologics 2026 2Q Reviewed Consolidated Interim FS (30-Jun-26, K-IFRS, English; also filed in DART 반기보고서 2026.06) | T13: ST Pharm 반기연결검토보고서 (reviewed consolidated interim FS, 30-Jun-26; attachment to DART 반기보고서 2026.06) | U13: ROVI Informe Financiero Semestral H1-2026 (CNMV filing; condensed consolidated interim FS at 30-Jun-26, IFRS, Spanish) | V13: Eurofins Half Year Report 2026 (interim condensed consolidated FS at 30-Jun-26, IFRS) | W13: SGS 2026 Half Year Results Interim Report (condensed consolidated FS at 30-Jun-26, IFRS) | X13: Bureau Veritas 2026 Half-Year Financial Report (condensed consolidated FS at 30-Jun-26, IFRS) | Y13: Intertek 2026 Half-year Financial Report RNS (31-Jul-26; condensed consolidated interim FS at 30-Jun-26, IFRS) – rendered PDF | Z13: Waters Form 10-Q, quarter ended 4-Jul-26 | AA13: Revvity Form 10-Q, quarter ended 5-Jul-26 | AB13: Thermo Fisher Form 10-Q, quarter ended 27-Jun-26 | AC13: Danaher Form 10-Q, quarter ended 26-Jun-26 | AD13: Agilent Form 10-Q, quarter ended 31-Jul-26 (Q3 FY26) | AE13: WuXi Biologics 2026 Interim Results Announcement (HKEX, 25-Aug-26; condensed consolidated FS at 30-Jun-26, IFRS, RMB) | AF13: OXB Interim Results H1 2026 RNS (22-Sep-26; unaudited condensed consolidated FS at 30-Jun-26, IFRS) – rendered PDF
E15: SUMMARY STATS
E17: FactSet Name | L17: Qiagen Nv | M17: Bio-Rad Laboratories, Inc. | N17: Neogen Corp. | O17: Maravai Lifesciences Holdings, Inc. | P17: Bachem Holding Ag | Q17: Siegfried Holding Ag | R17: Lonza Group Ag | S17: Samsung Biologics Co., Ltd. | T17: St Pharm Co., Ltd. | U17: Laboratorios Farmaceúticos Rovi Sa | V17: Eurofins Scientific Se | W17: Sgs Sa | X17: Bureau Veritas Sa | Y17: Intertek Group Plc | Z17: Waters Corp. | AA17: Revvity, Inc. | AB17: Thermo Fisher Scientific, Inc. | AC17: Danaher Corp. | AD17: Agilent Technologies, Inc. | AE17: Wuxi Biologics (Cayman), Inc. | AF17: Oxford Biomedica Plc
E18: Primary Stock Exchange | K18: -- | L18: NYSE | M18: NYSE | N18: NASDAQ | O18: NASDAQ | P18: SIX Swiss | Q18: SIX Swiss | R18: SIX Swiss | S18: Korea | T18: Korea | U18: Madrid | V18: Euronext Paris | W18: SIX Swiss | X18: Euronext Paris | Y18: London | Z18: NYSE | AA18: NYSE | AB18: NYSE | AC18: NYSE | AD18: NYSE | AE18: Hong Kong | AF18: London
E19: Country Located | K19: -- | L19: NETHERLANDS | M19: UNITED STATES | N19: UNITED STATES | O19: UNITED STATES | P19: SWITZERLAND | Q19: SWITZERLAND | R19: SWITZERLAND | S19: SOUTH KOREA | T19: SOUTH KOREA | U19: SPAIN | V19: LUXEMBOURG | W19: SWITZERLAND | X19: FRANCE | Y19: UNITED KINGDOM | Z19: UNITED STATES | AA19: UNITED STATES | AB19: UNITED STATES | AC19: UNITED STATES | AD19: UNITED STATES | AE19: CHINA | AF19: UNITED KINGDOM
E20: ="Closing Price - "&$F$4&" ("&TEXT(F2,"mm/dd/yy")&")" -> Closing Price - USD (09/21/26) | L20: 47.57 | M20: 377.33 | N20: 13.61 | O20: 7.17 | P20: 98.42856 | Q20: 88.439514 | R20: 668.53455 | S20: 1014.9492 | T20: 65.87759 | U20: 67.5186 | V20: 89.558235 | W20: 115.09319 | X20: 31.149195 | Y20: 50.574547 | Z20: 423.92 | AA20: 143.59 | AB20: 658.76 | AC20: 215.84 | AD20: 161.94 | AE20: 6.7551637 | AF20: 6.2186775
E21: FDSO | K21: =+K145 -> 0 | L21: =+L145 -> 209.581 | M21: =+M145 -> 27.251058 | N21: =+N145 -> 222.47012 | O21: =+O145 -> 271.28262 | P21: =+P145 -> 74.93554 | Q21: =+Q145 -> 44.04206 | R21: =+R145 -> 70.091729 | ... AF21: =+AF145 -> 126.61352
E22: Equity Value | G22: MC | K22: =+K20*K21 -> 0 | L22: =+L20*L21 -> 9969.7682 | M22: =+M20*M21 -> 10282.642 | N22: =+N20*N21 -> 3027.8184 | O22: =+O20*O21 -> 1945.0964 | P22: =+P20*P21 -> 7375.7973 | Q22: =+Q20*Q21 -> 3895.0584 | R22: =+R20*R21 -> 46858.743 | ... AF22: =+AF20*AF21 -> 787.36867
E23: Plus: Total Debt | K23: =+K65 -> 0 | L23: =+L65 -> 1661.8144 | M23: =+M65 -> 1249.204 | N23: =+N65 -> 793.7 | O23: =+O65 -> 176.696 | P23: =+P65 -> 257.06045 | Q23: =+Q65 -> 1237.122 | R23: =+R65 -> 5010.5791 | ... AF23: =+AF65 -> 71.191015
E24: Plus: Minority Interest | K24: =K75 -> 0 | L24: =L75 -> 0 | M24: =M75 -> 0 | N24: =N75 -> 0 | O24: =O75 -> 0 | P24: =P75 -> 0 | Q24: =Q75 -> -0.95732328 | R24: =R75 -> 39.528187 | ... AF24: =AF75 -> 0
E25: Plus: Preferred Stock | K25: =+K79 -> 0 | L25: =+L79 -> 0 | M25: =+M79 -> 0 | N25: =+N79 -> 0 | O25: =+O79 -> 0 | P25: =+P79 -> 0 | Q25: =+Q79 -> 0 | R25: =+R79 -> 0 | ... AF25: =+AF79 -> 0
E26: Less: Total Cash | K26: =-K50 -> 0 | L26: =-L50 -> -810.5 | M26: =-M50 -> -6947.6 | N26: =-N50 -> -185.5 | O26: =-O50 -> -70.091 | P26: =-P50 -> -63.707085 | Q26: =-Q50 -> -129.89951 | R26: =-R50 -> -3245.0171 | ... AF26: =-AF50 -> -99.535206
E27: Enterprise Value | G27: EV | K27: =SUM(K22:K26) -> 0 | L27: =SUM(L22:L26) -> 10821.083 | M27: =SUM(M22:M26) -> 4584.2457 | N27: =SUM(N22:N26) -> 3636.0184 | O27: =SUM(O22:O26) -> 2051.7014 | P27: =SUM(P22:P26) -> 7569.1507 | Q27: =SUM(Q22:Q26) -> 5001.3235 | R27: =SUM(R22:R26) -> 48663.833 | ... AF27: =SUM(AF22:AF26) -> 759.02448
E28: =+"Check: FactSet EV - "&F4 -> Check: FactSet EV - USD | L28: 10604.966 | M28: 9868.0266 | N28: 3586.675 | O28: 1318.2123 | P28: 7569.8455 | Q28: 4900.2446 | R28: 51359.608 | S28: 46319.322 | T28: 1304.9473 | U28: 3448.6867 | V28: 22037.554 | W28: 27556.716 | X28: 16397.365 | Y28: 9875.4631 | Z28: 26213.821 | AA28: 18346.668 | AB28: 283001.96 | AC28: 176249.38 | AD28: 48020.02 | AE28: 27673.285 | AF28: 863.14023
E29: Memo: Net Debt | K29: =+K23+K26 -> 0 | L29: =+L23+L26 -> 851.3144 | M29: =+M23+M26 -> -5698.396 | N29: =+N23+N26 -> 608.2 | O29: =+O23+O26 -> 106.605 | P29: =+P23+P26 -> 193.35336 | Q29: =+Q23+Q26 -> 1107.2225 | R29: =+R23+R26 -> 1765.562 | ... AF29: =+AF23+AF26 -> -28.344191
A31: x | B31: x | E31: =+"MARKET DATA - "&F4 -> MARKET DATA - USD
E33: 52-Wk High - Closing Price | L33: 54.515812 | M33: 390.34 | N33: 13.61 | O33: 9 | P33: 105.38852 | Q33: 130.24225 | R33: 739.6612 | S33: 1336.8712 | T33: 114.48543 | U33: 100.70519 | V33: 89.558235 | W33: 126.485 | X33: 34.736195 | Y33: 67.77288 | Z33: 429.72 | AA33: 146.73 | AB33: 658.76 | AC33: 242.05 | AD33: 161.94 | AE33: 6.7551637 | AF33: 12.220962
E34: % 52-Wk High | K34: =IFERROR(MIN(K20/K33,1),0) -> 0 | L34: =MIN(L20/L33,1) -> 0.87259087 | M34: =MIN(M20/M33,1) -> 0.96667008 | N34: =MIN(N20/N33,1) -> 1 | O34: =MIN(O20/O33,1) -> 0.79666667 | P34: =MIN(P20/P33,1) -> 0.93395903 | Q34: =MIN(Q20/Q33,1) -> 0.67903859 | R34: =MIN(R20/R33,1) -> 0.90383888 | S34: =MIN(S20/S33,1) -> 0.75919742 | ... AF34: =MIN(AF20/AF33,1) -> 0.50885335
E35: 52-Wk Low - Closing Price | L35: 39.81053 | M35: 241.71 | N35: 5.36 | O35: 2.69 | P35: 60.555595 | Q35: 83.51511 | R35: 591.5457 | S35: 809.95667 | T35: 58.919685 | U35: 61.39975 | V35: 65.98295 | W35: 100.83088 | X35: 28.841074 | Y35: 47.78617 | Z35: 283.32 | AA35: 82.26 | AB35: 438.34 | AC35: 161.91 | AD35: 110.24 | AE35: 3.789667 | AF35: 5.7261195
E36: LTM - Closing Price | L36: 49.696228 | M36: 284.07 | N36: 5.61 | O36: 2.7 | P36: 83.00321 | Q36: 105.76621 | R36: 683.1416 | S36: 1081.02 | T36: 67.426285 | U36: 69.54857 | V36: 73.558044 | W36: 102.79822 | X36: 30.359156 | Y36: 51.842415 | Z36: 300.87 | AA36: 86.72 | AB36: 479.58 | AC36: 193.29 | AD36: 126.32 | AE36: 4.8589454 | AF36: 7.981936
E37: Begin of Year (YTD) - Closing Price | L37: 47.33686 | M37: 302.99 | N37: 6.99 | O37: 3.25 | P37: 75.73171 | Q37: 94.316956 | R37: 679.9418 | S37: 1176.6339 | T37: 82.74617 | U37: 74.577576 | V37: 73.28568 | W37: 114.87451 | X37: 31.921553 | Y37: 62.22201 | Z37: 379.83 | AA37: 96.75 | AB37: 579.45 | AC37: 228.92 | AD37: 136.07 | AE37: 4.039314 | AF37: 8.298959
E38: =+"Local Price - Not Necessarily "&F4 -> Local Price - Not Necessarily USD | L38: 47.57 | M38: 377.33 | N38: 13.61 | O38: 7.17 | P38: 80.8 | Q38: 72.6 | R38: 548.8 | S38: 1402000 | T38: 91000 | U38: 58.85 | V38: 78.06 | W38: 94.48 | X38: 27.15 | Y38: 37.7 | Z38: 423.92 | AA38: 143.59 | AB38: 658.76 | AC38: 215.84 | AD38: 161.94 | AE38: 53 | AF38: 4.65
E39: All Time High - Closing Price | L39: 66.50475 | M39: 825.77 | N39: 48.335 | O39: 60.62 | P39: 167.6 | Q39: 118.20001 | R39: 784.6 | S39: 1965000 | T39: 168700 | U39: 91.5 | V39: 126.44 | W39: 122.36 | X39: 31.3 | Y39: 64.4 | Z39: 429.72 | AA39: 201.06 | AB39: 667.24 | AC39: 332.43 | AD39: 179.28 | AE39: 145.6 | AF39: 54.096256
A41: x | B41: x | E41: BALANCE SHEET
E43: Cash & Equivalents (Local) | L43: 768.5 | M43: 517 | N43: 185.5 | O43: 70.091 | P43: 51.574 | Q43: 104.672 | R43: 487 | S43: 288575.63 | T43: 53834.18 | U43: 126.969 | V43: 617.8 | W43: 1300 | X43: 942.1 | Y43: 438.6 | Z43: 539 | AA43: 1022.943 | AB43: 4064 | AC43: 4348 | AD43: 1758 | AE43: 8904.44 | AF43: 75.283
E44: Short-Term Investments | L44: 25 | M44: 1101.5 | N44: 0 | O44: 0 | P44: 0 | Q44: 0.488 | R44: 0 | S44: 1900000 | T44: 110830 | U44: 1.103 | V44: 0 | W44: 0 | X44: 0 | Y44: 0 | Z44: 0 | AA44: 0 | AB44: 0 | AC44: 0 | AD44: 0 | AE44: 4123.839 | AF44: 0
E45: Long-Term Investments | M45: 5295.2 | S45: 0.006
E46: Investment in Associates (JVs) | K46: 0 | L46: 17 | M46: 33.9 | N46: 0 | O46: 0 | P46: 0 | Q46: 0 | R46: 33 | S46: 51938.447 | T46: 0 | U46: 19.252 | V46: 5.6 | W46: 6 | X46: 0 | Y46: 0 | Z46: 0 | AA46: 0 | AB46: 178 | AC46: 0 | AD46: 0 | AE46: 1210.82 | AF46: 0
E47: PF Cash Adjustment | R47: 2107 | S47: 3000940
E48: PF Cash Adjustment | T48: -30000
E49: PF Cash Adjustment
...

Sheet Spread Notes
A1: Hand spread of trading comps – methodology and judgements
C2: Each hand-spread cell on the Spreads tab is in blue and has a note giving the filing, page number and calculation. Page numbers are the printed page numbers of the document unless the note says "PDF p." (rendered RNS / unnumbered documents) or "DART p.". FactSet formulas were frozen to their cached values; any company cell without a "Hand spread" note is FactSet market data or consensus (prices, 52-week data, forward estimates, dividends).
C3: FactSet / external links removed: pricing date (F2) is now a hard-coded 21-Sep-26; the pre-IFRS 16 switch is now cell F5 (1 = pre-IFRS 16); tax rates (row 71) kept as cached values; IFRS 16 LTM lease data (rows 327–328) are now hand-spread.
A5: General methodology
A6: Balance sheet | C6: Latest reported balance sheet (30-Jun-26 for all except Neogen 31-May-26, Waters 4-Jul-26, Revvity 5-Jul-26, TMO 27-Jun-26, DHR 26-Jun-26, Agilent 31-Jul-26). Debt at carrying value (current + non-current borrowings, incl. converts – convert treatment in rows 88–113).
A7: Pre-IFRS 16 basis | C7: IFRS reporters: IFRS 16 lease liabilities go in row 58 (or are kept within reported debt where the company does so – ROVI, Eurofins – and row 62 is then hard-coded); row 62 picks them up and row 63 reverses them when F5 = 1. LTM ROU depreciation (row 327) and lease interest (row 328) are deducted from EBITDA, and lease interest from EBIT (rows 329–330). LTM = FY25 + H1-26 − H1-25 where the halves are disclosed; FY25 is used as a proxy where they are not (stated in the note).
A8: US GAAP / Swiss GAAP FER | C8: US GAAP (ASC 842) operating leases are already within EBITDA and outside debt, so no adjustment. Bachem and Siegfried report under Swiss GAAP FER (operating leases off balance sheet), so they are already pre-IFRS 16.
A9: Income statement | C9: FY23–FY25 actuals from the annual reports / 10-Ks, converted to USD at each year's ECB average rate (FX tab). EBIT = reported operating profit. EBITDA: US companies = EBIT + D&A + non-cash impairments; IFRS/FER companies = company-reported EBITDA where one is given, otherwise EBIT + D&A (+ impairment). NI = attributable to shareholders, continuing operations where there are discontinued operations. EPS = diluted. CapEx = purchases of PP&E (and software / intangibles where reported in one line).
A10: Calendarisation | C10: Neogen (May FYE): 5/12 × FY ending May + 7/12 × FY ending the next May. Agilent (Oct FYE): FY − Q1 of that FY + Q1 of the next FY. Both are shown on a December basis.
A11: By-nature reporters | C11: Eurofins, SGS, Bureau Veritas and Intertek do not report gross profit, R&D or SG&A. These are shown as "n.a."
A12: Pensions | C12: Net DB pension deficit only (surplus entered as negative), tax-effected at the row 71 rate; OPEB / other employee benefits excluded.
A13: Shares & dilution | C13: Basic shares from the latest cover page / share-capital disclosure, net of treasury shares and EBT shares. Options are split into tranches by strike where disclosed; RSUs/PSUs at nil strike (PSUs at target). Treasury-stock dilution uses the existing template formulas.
A14: FX | C14: ECB reference rates, crossed through EUR (FX tab). Balance-sheet items: spot at 30-Jun-26. Options and converts: spot at each column's pricing date. The FactSet balance-sheet FX for CHF/EUR/GBP columns was taken at an inconsistent date (e.g. CHF 1.1977 vs ECB 1.2353 at 30-Jun-26) and has been replaced.
A16: Company-specific judgements and flags
A17: QGEN-US | B17: Qiagen | C17: Converts: net-share-settled notes treated in the convert section (book / face / conversion price). Pricing date kept at 16-Jan-26 as in the backup.
A18: BIO-US | B18: Bio-Rad | C18: Sartorius stake ($5,295m, fair value) included in long-term investments (row 45) – FactSet excluded it. Class B shares included in row 138.
A19: NEOG-US | B19: Neogen | C19: Calendarised (May FYE). Balance sheet at 31-May-26 (FY26 10-K).
A20: MRVI-US | B20: Maravai | C20: Class B shares (110.68m, exchangeable into Class A) included in row 138, with NCI set to 0 to avoid double counting.
A21: BANB-CH | B21: Bachem | C21: Swiss GAAP FER – no IFRS 16 adjustment.
A22: SFZN-CH | B22: Siegfried | C22: Swiss GAAP FER – no IFRS 16 adjustment.
A23: LONN-CH | B23: Lonza | C23: PF cash CHF 2,107m = Capsules & Health Ingredients net assets held for sale. FY23 includes C&HI (not restated – not comparable). CapEx is total group. Associates (CHF 33m) are the 31-Dec-25 figure.
A24: 207940-KR | B24: Samsung Biologics | C24: Rights issue PF: cash +KRW 3,000,940m, shares +2.27m. FY23 includes Samsung Bioepis (pre spin-off). The EPS share base changed after the spin-off.
A25: 237690-KR | B25: ST Pharm | C25: CB call PF: cash −30,000; debt −24,198.7; residual CB book 17,383.4 / face 21,551 / conversion price KRW 79,648. Options in 4 strike tranches.
A26: ROVI-ES | B26: ROVI | C26: Lease liabilities are included in reported debt, so row 62 is hard-coded at EUR 12.7m. Lease interest is not disclosed separately (nil).
A27: ERF-FR | B27: Eurofins | C27: Hybrid capital (EUR 1,000m) treated as preferred (row 77), with equity reduced accordingly. Warrants: 903,570 shares @ EUR 52.965. Lease liabilities are included in reported debt (row 62 is hard-coded). MET Labs is held for sale (~EUR 575m EV) – noted only.
A28: SGSN-CH | B28: SGS | C28: 477,782 PSOs excluded (no strike disclosed).
... A36: OXB-GB | B36: Oxford Biomedica | C36: Basic shares per the 1-Oct-26 TVR (121.05m) less 30,519 EBT shares. Options from the AR25 range table (31-Dec-25). EBITDA is statutory (EBIT + D&A + impairment); the company's "Operating EBITDA" also adds back share-based payments and is not used. FY25 EBIT includes a GBP 9.9m bargain-purchase gain. R&D = "Innovation costs"; SG&A = commercial + administration.
A38: Primary sources (balance sheet / share data) by company
A39: QGEN-US | B39: Qiagen | C39: QIAGEN Q2-26 Quarterly Report (Form 6-K Ex.99.1 filed 7-Aug-26), quarter ended 30-Jun-26 QIAGEN Form 20-F FY25 (Financial Report 2025, YE 31-Dec-25) QIAGEN Form 20-F FY25 (Financial Report 2025, YE 31-Dec-25), FY2025 (2025-01-01 to 2025-12-31) QIAGEN Form 20-F FY25 (Financial Report 2025, YE 31-Dec-25), FY2024 (2024-01-01 to 2024-12-31) QIAGEN Form 20-F FY25 (Financial Report 2025, YE 31-Dec-25), FY2023 (2023-01-01 to 2023-12-31) QIAGEN Form 20-F FY25 (Financial Report 2025, YE 31-Dec-25), FY2025 QIAGEN Form 20-F FY25 (Financial Report 2025, YE 31-Dec-25), FY2024 QIAGEN Form 20-F FY25 (Financial Report 2025, YE 31-Dec-25), FY2023
A40: BIO-US | B40: Bio-Rad | C40: Bio-Rad Form 10-Q, quarter ended 30-Jun-26 Bio-Rad Form 10-K FY25 (YE 31-Dec-25) Bio-Rad Form 10-Q, quarter ended 30-Jun-26, cover page Bio-Rad Form 10-K FY25 (YE 31-Dec-25), FY2025 (2025-01-01 to 2025-12-31) Bio-Rad Form 10-K FY25 (YE 31-Dec-25), FY2024 (2024-01-01 to 2024-12-31) Bio-Rad Form 10-K FY25 (YE 31-Dec-25), FY2023 (2023-01-01 to 2023-12-31) Bio-Rad Form 10-K FY25 (YE 31-Dec-25), FY2025 Bio-Rad Form 10-K FY25 (YE 31-Dec-25), FY2024
A41: NEOG-US | B41: Neogen | C41: Neogen Form 10-K FY26 (YE 31-May-26) Neogen Form 10-K FY26 (YE 31-May-26), cover page Revenue CY2025 (Neogen FY ends 31-May; calendarised to Dec YE by month-weighting, consistent with FactSet CALA basis) Revenue CY2024 (Neogen FY ends 31-May; calendarised to Dec YE by month-weighting, consistent with FactSet CALA basis) Revenue CY2023 (Neogen FY ends 31-May; calendarised to Dec YE by month-weighting, consistent with FactSet CALA basis) Gross profit CY2025 (Neogen FY ends 31-May; calendarised to Dec YE by month-weighting, consistent with FactSet CALA basis) Gross profit CY2024 (Neogen FY ends 31-May; calendarised to Dec YE by month-weighting, consistent with FactSet CALA basis) Gross profit CY2023 (Neogen FY ends 31-May; calendarised to Dec YE by month-weighting, consistent with FactSet CALA basis)
A42: MRVI-US | B42: Maravai | C42: Maravai Form 10-Q, quarter ended 30-Jun-26 Maravai Form 10-Q, quarter ended 30-Jun-26, cover page Maravai Form 10-K FY25 (YE 31-Dec-25) Maravai Form 10-K FY25 (YE 31-Dec-25), FY2025 (2025-01-01 to 2025-12-31) Maravai Form 10-K FY25 (YE 31-Dec-25), FY2024 (2024-01-01 to 2024-12-31) Maravai Form 10-K FY25 (YE 31-Dec-25), FY2023 (2023-01-01 to 2023-12-31) Maravai Form 10-K FY25 (YE 31-Dec-25), FY2025 Maravai Form 10-K FY25 (YE 31-Dec-25), FY2024
A43: BANB-CH | B43: Bachem | C43: Bachem Half-Year Report 2026 (30-Jun-26, Swiss GAAP FER) Bachem Annual Report 2025 (Financial Report, Swiss GAAP FER) Bachem Annual Report 2024 (Financial Report) Bachem Annual Report 2025 (Financial Report, Swiss GAAP FER), company-reported EBITDA FY25 CHF 214.7m (p.10 key figures) = EBIT 167,303 + depreciation 43,453 (Note 13 Bachem Annual Report 2025 (Financial Report, Swiss GAAP FER), company-reported EBITDA FY24 CHF 176.3m (p.10) = EBIT 133,048 + depreciation 39,039 (Note 13 Bachem Annual Report 2024 (Financial Report), company-reported EBITDA FY23 CHF 166.7m (p.10) = EBIT 129,380 + depreciation 33,896 (Note 13
A44: SFZN-CH | B44: Siegfried | C44: Siegfried Half-Year Report 2026 (30-Jun-26, Swiss GAAP FER) Siegfried Annual Report 2025 Siegfried Annual Report 2024 (Full Report)
A45: LONN-CH | B45: Lonza | C45: Lonza Half-Year Report 2026 (30-Jun-26, IFRS; via SGXNet) Lonza Annual Report 2025 (IFRS; continuing operations, C&HI restated as discontinued) Lonza Annual Report 2024 (IFRS, as originally reported
A46: 207940-KR | B46: Samsung Biologics | C46: Samsung Biologics 2026 2Q Reviewed Consolidated Interim FS (30-Jun-26, K-IFRS, English; also filed in DART 반기보고서 2026.06) Samsung Biologics DART 주요사항보고서(유상증자결정) 28-Aug-26 & press release 28-Aug-26 Samsung Biologics FY2025 Audited Consolidated FS (K-IFRS, English; Bioepis spin-off restated as discontinued) Samsung Biologics FY2024 연결감사보고서 (DART 사업보고서 2024.12 attachment, as originally reported
A47: 237690-KR | B47: ST Pharm | C47: ST Pharm 반기연결검토보고서 (reviewed consolidated interim FS, 30-Jun-26; attachment to DART 반기보고서 2026.06) ST Pharm 반기보고서 2026.06 (DART) p.9 (주식의 총수) ST Pharm 반기보고서 2026.06 (DART) p.69 (주식매수선택권 ST Pharm 반기보고서 2026.06 (DART) p.69 ST Pharm 연결감사보고서 FY2025 (attachment to DART 사업보고서 2025.12) p.10 ST Pharm 연결감사보고서 FY2024 (attachment to DART 사업보고서 2024.12) p.10 ST Pharm 연결감사보고서 FY2025 (attachment to DART 사업보고서 2025.12) p.69 (Note 28) ST Pharm 연결감사보고서 FY2025 (attachment to DART 사업보고서 2025.12) p.69
A48: ROVI-ES | B48: ROVI | C48: ROVI Informe Financiero Semestral H1-2026 (CNMV filing; condensed consolidated interim FS at 30-Jun-26, IFRS, Spanish) ROVI Consolidated Annual Accounts FY2025 (IFRS, English translation, incl. Consolidated Management Report) ROVI Consolidated Annual Accounts FY2024 (IFRS, English translation) ROVI Consolidated Annual Accounts FY2025 (IFRS, English translation, incl. Consolidated Management Report), Consolidated Management Report p.2 (2.1 Business performance) ROVI Consolidated Annual Accounts FY2025 (IFRS, English translation, incl. Consolidated Management Report), Management Report p.2 ROVI Consolidated Annual Accounts FY2024 (IFRS, English translation), Management Report p.2
A49: ERF-FR | B49: Eurofins | C49: Eurofins Half Year Report 2026 (interim condensed consolidated FS at 30-Jun-26, IFRS) Eurofins Annual Report 2025 (IFRS) Eurofins Annual Report 2024 (IFRS) Eurofins Annual Report 2025 (IFRS) p.133 / Eurofins Annual Report 2024 (IFRS) p.247
A50: SGSN-CH | B50: SGS | C50: SGS 2026 Half Year Results Interim Report (condensed consolidated FS at 30-Jun-26, IFRS) SGS 2025 Integrated Report SGS 2024 Integrated Report
...

Sheet FX
A1: FX rates – USD per 1 unit of local currency
A2: Source: ECB euro foreign exchange reference rates (data-api.ecb.europa.eu, series EXR.D.<CCY>.EUR.SP00.A), crossed through EUR (USD per CCY = USD/EUR ÷ CCY/EUR). Averages = simple mean of all ECB daily fixings in the calendar year. Spot = ECB fixing on the date (or the last fixing before it).
A4: Currency | B4: Avg 2023 | C4: Avg 2024 | D4: Avg 2025 | E4: Spot 30-Jun-26 (balance sheet date) | F4: Spot 21-Sep-26 (pricing date) | G4: Spot 16-Jan-26 (QGEN pricing date) | H4: Spot 9-Apr-26 (ITRK pricing date)
A5: USD | B5: 1 | C5: 1 | D5: 1 | E5: 1 | F5: 1 | G5: 1 | H5: 1
A6: CHF | B6: 1.1129794 | C6: 1.1365712 | D6: 1.2062357 | E6: 1.2352558 | F6: 1.2174189 | G6: 1.2473961 | H6: 1.2646104
A7: EUR | B7: 1.0812686 | C7: 1.0823805 | D7: 1.1299831 | E7: 1.1394 | F7: 1.149 | G7: 1.1617 | H7: 1.1685
A8: GBP | B8: 1.2433758 | C8: 1.2785942 | D8: 1.3184218 | E8: 1.3221472 | F8: 1.3394731 | G8: 1.3399077 | H8: 1.3422857
A9: KRW | B9: 0.00076563 | C9: 0.00073382 | D9: 0.00070394 | E9: 0.00064479 | F9: 0.00072877 | G9: 0.00067892 | H9: 0.00067591
A10: HKD | B10: 0.12773432 | C10: 0.12816399 | D10: 0.12826395 | E10: 0.12752098 | F10: 0.12746273 | G10: 0.12820456 | H10: 0.12763378
A11: CNY | B11: 0.14124959 | C11: 0.13898663 | D11: 0.13915023 | E11: 0.14737305 | F11: 0.14935656 | G11: 0.14347821 | H11: 0.14631306

Sheet FactSet vs Hand
A1: FactSet vs Hand spread – key lines (FactSet = frozen cached values from the original backup; Hand = live link to Spreads)
A3: Ticker | B3: Company | C3: Row | D3: Item | E3: FactSet | F3: Hand spread | G3: Difference | H3: Diff %
A4: QGEN-US | B4: Qiagen | C4: 43 | D4: Cash & equivalents (local) | E4: 1098.918 | F4: =Spreads!L43 -> 768.5 | G4: =IF(AND(ISNUMBER(E4),ISNUMBER(F4)),F4-E4,"") -> -330.418 | H4: =IF(AND(ISNUMBER(E4),ISNUMBER(F4)),IF(E4=0,"",F4/E4-1),"") -> -0.30067576
A5: QGEN-US | B5: Qiagen | C5: 44 | D5: ST investments (local) | F5: =Spreads!L44 -> 25 | G5: =IF(AND(ISNUMBER(E5),ISNUMBER(F5)),F5-E5,"") | H5: =IF(AND(ISNUMBER(E5),ISNUMBER(F5)),IF(E5=0,"",F5/E5-1),"")
A6: QGEN-US | B6: Qiagen | C6: 45 | D6: LT investments (local) | F6: =Spreads!L45 -> 0 | G6: =IF(AND(ISNUMBER(E6),ISNUMBER(F6)),F6-E6,"") | H6: =IF(AND(ISNUMBER(E6),ISNUMBER(F6)),IF(E6=0,"",F6/E6-1),"")
A7: QGEN-US | B7: Qiagen | C7: 46 | D7: Associates / JVs (local) | E7: 12.9 | F7: =Spreads!L46 -> 17 | G7: =IF(AND(ISNUMBER(E7),ISNUMBER(F7)),F7-E7,"") -> 4.1 | H7: =IF(AND(ISNUMBER(E7),ISNUMBER(F7)),IF(E7=0,"",F7/E7-1),"") -> 0.31782946
A8: QGEN-US | B8: Qiagen | C8: 55 | D8: ST debt (local) | E8: 28.837 | F8: =Spreads!L55 -> 16.517 | G8: =IF(AND(ISNUMBER(E8),ISNUMBER(F8)),F8-E8,"") -> -12.32 | H8: =IF(AND(ISNUMBER(E8),ISNUMBER(F8)),IF(E8=0,"",F8/E8-1),"") -> -0.42722891
A9: QGEN-US | B9: Qiagen | C9: 56 | D9: LT debt (local) | E9: 1783.535 | F9: =Spreads!L56 -> 1627.105 | G9: =IF(AND(ISNUMBER(E9),ISNUMBER(F9)),F9-E9,"") -> -156.43 | H9: =IF(AND(ISNUMBER(E9),ISNUMBER(F9)),IF(E9=0,"",F9/E9-1),"") -> -0.087707839
A10: QGEN-US | B10: Qiagen | C10: 58 | D10: Other debt / leases (local) | F10: =Spreads!L58 -> 0 | G10: =IF(AND(ISNUMBER(E10),ISNUMBER(F10)),F10-E10,"") | H10: =IF(AND(ISNUMBER(E10),ISNUMBER(F10)),IF(E10=0,"",F10/E10-1),"")
A11: QGEN-US | B11: Qiagen | C11: 62 | D11: IFRS 16 lease liabilities (local) | E11: 0 | F11: =Spreads!L62 -> 0 | G11: =IF(AND(ISNUMBER(E11),ISNUMBER(F11)),F11-E11,"") -> 0 | H11: =IF(AND(ISNUMBER(E11),ISNUMBER(F11)),IF(E11=0,"",F11/E11-1),"")
A12: QGEN-US | B12: Qiagen | C12: 70 | D12: Net pension deficit (local) | E12: 9.2 | F12: =Spreads!L70 -> 9.2 | G12: =IF(AND(ISNUMBER(E12),ISNUMBER(F12)),F12-E12,"") -> 0 | H12: =IF(AND(ISNUMBER(E12),ISNUMBER(F12)),IF(E12=0,"",F12/E12-1),"") -> 0
A13: QGEN-US | B13: Qiagen | C13: 74 | D13: Minority interest (local) | E13: 0 | F13: =Spreads!L74 -> 0 | G13: =IF(AND(ISNUMBER(E13),ISNUMBER(F13)),F13-E13,"") -> 0 | H13: =IF(AND(ISNUMBER(E13),ISNUMBER(F13)),IF(E13=0,"",F13/E13-1),"")
A14: QGEN-US | B14: Qiagen | C14: 77 | D14: Preferred (local) | E14: 0 | F14: =Spreads!L77 -> 0 | G14: =IF(AND(ISNUMBER(E14),ISNUMBER(F14)),F14-E14,"") -> 0 | H14: =IF(AND(ISNUMBER(E14),ISNUMBER(F14)),IF(E14=0,"",F14/E14-1),"")
A15: QGEN-US | B15: Qiagen | C15: 81 | D15: Equity (local) | E15: 3778.154 | F15: =Spreads!L81 -> 3357.74 | G15: =IF(AND(ISNUMBER(E15),ISNUMBER(F15)),F15-E15,"") -> -420.414 | H15: =IF(AND(ISNUMBER(E15),ISNUMBER(F15)),IF(E15=0,"",F15/E15-1),"") -> -0.11127498
A16: QGEN-US | B16: Qiagen | C16: 137 | D16: Basic shares (m) | E16: 206.8 | F16: =Spreads!L137 -> 206.495 | G16: =IF(AND(ISNUMBER(E16),ISNUMBER(F16)),F16-E16,"") -> -0.305 | H16: =IF(AND(ISNUMBER(E16),ISNUMBER(F16)),IF(E16=0,"",F16/E16-1),"") -> -0.0014748549
A17: QGEN-US | B17: Qiagen | C17: 145 | D17: FDSO (m) | E17: 206.8 | F17: =Spreads!L145 -> 209.581 | G17: =IF(AND(ISNUMBER(E17),ISNUMBER(F17)),F17-E17,"") -> 2.781 | H17: =IF(AND(ISNUMBER(E17),ISNUMBER(F17)),IF(E17=0,"",F17/E17-1),"") -> 0.013447776
A18: QGEN-US | B18: Qiagen | C18: 50 | D18: Total cash (USD) | E18: 1111.818 | F18: =Spreads!L50 -> 810.5 | G18: =IF(AND(ISNUMBER(E18),ISNUMBER(F18)),F18-E18,"") -> -301.318 | H18: =IF(AND(ISNUMBER(E18),ISNUMBER(F18)),IF(E18=0,"",F18/E18-1),"") -> -0.27101378
A19: QGEN-US | B19: Qiagen | C19: 65 | D19: Total debt (USD) | E19: 1819.1984 | F19: =Spreads!L65 -> 1661.8144 | G19: =IF(AND(ISNUMBER(E19),ISNUMBER(F19)),F19-E19,"") -> -157.384 | H19: =IF(AND(ISNUMBER(E19),ISNUMBER(F19)),IF(E19=0,"",F19/E19-1),"") -> -0.086512829
A20: QGEN-US | B20: Qiagen | C20: 27 | D20: Enterprise value (USD) | E20: 10544.856 | F20: =Spreads!L27 -> 10821.083 | G20: =IF(AND(ISNUMBER(E20),ISNUMBER(F20)),F20-E20,"") -> 276.22617 | H20: =IF(AND(ISNUMBER(E20),ISNUMBER(F20)),IF(E20=0,"",F20/E20-1),"") -> 0.026195347
A21: QGEN-US | B21: Qiagen | C21: 205 | D21: Revenue 2025 (USD) | E21: 2078 | F21: =Spreads!L205 -> 2089.999 | G21: =IF(AND(ISNUMBER(E21),ISNUMBER(F21)),F21-E21,"") -> 11.999 | H21: =IF(AND(ISNUMBER(E21),ISNUMBER(F21)),IF(E21=0,"",F21/E21-1),"") -> 0.0057743022
A22: QGEN-US | B22: Qiagen | C22: 245 | D22: EBIT 2025 (USD) | E22: 614.10443 | F22: =Spreads!L245 -> 465.851 | G22: =IF(AND(ISNUMBER(E22),ISNUMBER(F22)),F22-E22,"") -> -148.25343 | H22: =IF(AND(ISNUMBER(E22),ISNUMBER(F22)),IF(E22=0,"",F22/E22-1),"") -> -0.24141404
A23: QGEN-US | B23: Qiagen | C23: 265 | D23: EBITDA 2025 (USD) | E23: 757.10034 | F23: =Spreads!L265 -> 682.037 | G23: =IF(AND(ISNUMBER(E23),ISNUMBER(F23)),F23-E23,"") -> -75.06334 | H23: =IF(AND(ISNUMBER(E23),ISNUMBER(F23)),IF(E23=0,"",F23/E23-1),"") -> -0.099145828
A24: QGEN-US | B24: Qiagen | C24: 275 | D24: EBITDA 2025 pre-IFRS 16 (USD) | E24: 757.10034 | F24: =Spreads!L275 -> 682.037 | G24: =IF(AND(ISNUMBER(E24),ISNUMBER(F24)),F24-E24,"") -> -75.06334 | H24: =IF(AND(ISNUMBER(E24),ISNUMBER(F24)),IF(E24=0,"",F24/E24-1),"") -> -0.099145828
A25: QGEN-US | B25: Qiagen | C25: 285 | D25: Net income 2025 (USD) | E25: 516.01 | F25: =Spreads!L285 -> 424.88 | G25: =IF(AND(ISNUMBER(E25),ISNUMBER(F25)),F25-E25,"") -> -91.13 | H25: =IF(AND(ISNUMBER(E25),ISNUMBER(F25)),IF(E25=0,"",F25/E25-1),"") -> -0.1766051
A26: QGEN-US | B26: Qiagen | C26: 295 | D26: EPS 2025 (USD) | E26: 2.4736843 | F26: =Spreads!L295 -> 1.94 | G26: =IF(AND(ISNUMBER(E26),ISNUMBER(F26)),F26-E26,"") -> -0.5336843 | H26: =IF(AND(ISNUMBER(E26),ISNUMBER(F26)),IF(E26=0,"",F26/E26-1),"") -> -0.21574471
A27: QGEN-US | B27: Qiagen | C27: 339 | D27: CapEx 2025 (USD) | E27: 179.1758 | F27: =Spreads!L339 -> 201.049 | G27: =IF(AND(ISNUMBER(E27),ISNUMBER(F27)),F27-E27,"") -> 21.8732 | H27: =IF(AND(ISNUMBER(E27),ISNUMBER(F27)),IF(E27=0,"",F27/E27-1),"") -> 0.12207675
A28: QGEN-US | B28: Qiagen | C28: 327 | D28: LTM ROU depreciation (local) | E28: 0 | F28: =Spreads!L327 -> 0 | G28: =IF(AND(ISNUMBER(E28),ISNUMBER(F28)),F28-E28,"") -> 0 | H28: =IF(AND(ISNUMBER(E28),ISNUMBER(F28)),IF(E28=0,"",F28/E28-1),"")
A29: QGEN-US | B29: Qiagen | C29: 328 | D29: LTM lease interest (local) | E29: 0 | F29: =Spreads!L328 -> 0 | G29: =IF(AND(ISNUMBER(E29),ISNUMBER(F29)),F29-E29,"") -> 0 | H29: =IF(AND(ISNUMBER(E29),ISNUMBER(F29)),IF(E29=0,"",F29/E29-1),"")
A30: BIO-US | B30: Bio-Rad | C30: 43 | D30: Cash & equivalents (local) | E30: 1620.1 | F30: =Spreads!M43 -> 517 | G30: =IF(AND(ISNUMBER(E30),ISNUMBER(F30)),F30-E30,"") -> -1103.1 | H30: =IF(AND(ISNUMBER(E30),ISNUMBER(F30)),IF(E30=0,"",F30/E30-1),"") -> -0.6808839
A31: BIO-US | B31: Bio-Rad | C31: 44 | D31: ST investments (local) | F31: =Spreads!M44 -> 1101.5 | G31: =IF(AND(ISNUMBER(E31),ISNUMBER(F31)),F31-E31,"") | H31: =IF(AND(ISNUMBER(E31),ISNUMBER(F31)),IF(E31=0,"",F31/E31-1),"")
A32: BIO-US | B32: Bio-Rad | C32: 45 | D32: LT investments (local) | F32: =Spreads!M45 -> 5295.2 | G32: =IF(AND(ISNUMBER(E32),ISNUMBER(F32)),F32-E32,"") | H32: =IF(AND(ISNUMBER(E32),ISNUMBER(F32)),IF(E32=0,"",F32/E32-1),"")
A33: BIO-US | B33: Bio-Rad | C33: 46 | D33: Associates / JVs (local) | E33: 0 | F33: =Spreads!M46 -> 33.9 | G33: =IF(AND(ISNUMBER(E33),ISNUMBER(F33)),F33-E33,"") -> 33.9 | H33: =IF(AND(ISNUMBER(E33),ISNUMBER(F33)),IF(E33=0,"",F33/E33-1),"")
A34: BIO-US | B34: Bio-Rad | C34: 55 | D34: ST debt (local) | E34: 434.3 | F34: =Spreads!M55 -> 400.7 | G34: =IF(AND(ISNUMBER(E34),ISNUMBER(F34)),F34-E34,"") -> -33.6 | H34: =IF(AND(ISNUMBER(E34),ISNUMBER(F34)),IF(E34=0,"",F34/E34-1),"") -> -0.077365876
A35: BIO-US | B35: Bio-Rad | C35: 56 | D35: LT debt (local) | E35: 936.1 | F35: =Spreads!M56 -> 803 | G35: =IF(AND(ISNUMBER(E35),ISNUMBER(F35)),F35-E35,"") -> -133.1 | H35: =IF(AND(ISNUMBER(E35),ISNUMBER(F35)),IF(E35=0,"",F35/E35-1),"") -> -0.14218566
A36: BIO-US | B36: Bio-Rad | C36: 58 | D36: Other debt / leases (local) | F36: =Spreads!M58 -> 0 | G36: =IF(AND(ISNUMBER(E36),ISNUMBER(F36)),F36-E36,"") | H36: =IF(AND(ISNUMBER(E36),ISNUMBER(F36)),IF(E36=0,"",F36/E36-1),"")
A37: BIO-US | B37: Bio-Rad | C37: 62 | D37: IFRS 16 lease liabilities (local) | E37: 0 | F37: =Spreads!M62 -> 0 | G37: =IF(AND(ISNUMBER(E37),ISNUMBER(F37)),F37-E37,"") -> 0 | H37: =IF(AND(ISNUMBER(E37),ISNUMBER(F37)),IF(E37=0,"",F37/E37-1),"")
A38: BIO-US | B38: Bio-Rad | C38: 70 | D38: Net pension deficit (local) | E38: 57.6 | F38: =Spreads!M70 -> 57.6 | G38: =IF(AND(ISNUMBER(E38),ISNUMBER(F38)),F38-E38,"") -> 0 | H38: =IF(AND(ISNUMBER(E38),ISNUMBER(F38)),IF(E38=0,"",F38/E38-1),"") -> 0
A39: BIO-US | B39: Bio-Rad | C39: 74 | D39: Minority interest (local) | E39: 0 | F39: =Spreads!M74 -> 0 | G39: =IF(AND(ISNUMBER(E39),ISNUMBER(F39)),F39-E39,"") -> 0 | H39: =IF(AND(ISNUMBER(E39),ISNUMBER(F39)),IF(E39=0,"",F39/E39-1),"")
A40: BIO-US | B40: Bio-Rad | C40: 77 | D40: Preferred (local) | E40: 0 | F40: =Spreads!M77 -> 0 | G40: =IF(AND(ISNUMBER(E40),ISNUMBER(F40)),F40-E40,"") -> 0 | H40: =IF(AND(ISNUMBER(E40),ISNUMBER(F40)),IF(E40=0,"",F40/E40-1),"")
A41: BIO-US | B41: Bio-Rad | C41: 81 | D41: Equity (local) | E41: 7173.9 | F41: =Spreads!M81 -> 7173.9 | G41: =IF(AND(ISNUMBER(E41),ISNUMBER(F41)),F41-E41,"") -> 0 | H41: =IF(AND(ISNUMBER(E41),ISNUMBER(F41)),IF(E41=0,"",F41/E41-1),"") -> 0
...
